Workbook
Name 切片器_二级费项2: #N/A
Name 切片器_月份: #N/A
Name 切片器_二级费项: #N/A

Sheet 财务映射表
A1: 财务费项 | C1: 成本费项
A2: 编码 | B2: 费项名称 | C2: 编码 | D2: 费项名称
A3: 6400 | B3: （二）营业成本
A4: 6401 | B4: 主营业务成本
A5: 6401.03 | B5: 物业管理业务成本
A6: 6401.03.01 | B6: 材料费用 | C6: 1.2 | D6: 物耗成本
A7: 6401.03.02 | B7: 外包费用
A8: 6401.03.02.01 | B8: 保洁外包 | C8: 1.1.1.3.3 | D8: 专业外包（人员）
A9: 6401.03.02.02 | B9: 安全外包 | C9: 1.1.1.1.3 | D9: 专业外包
A10: 6401.03.02.03 | B10: 绿化外包 | C10: 1.1.1.6.3 | D10: 专业外包（岗位）
C11: 1.1.1.6.4 | D11: 专业外包（面积）
A12: 6401.03.02.04 | B12: 消杀外包 | C12: 1.1.2.7.1 | D12: 消杀服务
A13: 6401.03.02.05 | B13: 电梯维保外保 | C13: 1.1.2.1 | D13: 电梯维保
A14: 6401.03.02.06 | B14: 设备设施维保外包 | C14: 1.1.2.3 | D14: 暖通维护
C15: 1.1.2.4 | D15: 弱电维护
C16: 1.1.2.5 | D16: 给排水维护
C17: 1.1.2.6 | D17: 设备维护
A18: 6401.03.02.07 | B18: 消防保外包 | C18: 1.1.2.2 | D18: 消防维保
A19: 6401.03.02.08 | B19: 装修垃圾清运外包 | C19: 1.1.2.7.2.4 | D19: 建筑/大件垃圾清运（新项目首次）
C20: 1.1.2.7.2.5 | D20: 建筑/大件垃圾清运（旧项目）
A21: 6401.03.02.09 | B21: 生活垃圾清运外包 | C21: 1.1.2.7.2.1 | D21: 生活垃圾清运（按240L桶）
C22: 1.1.2.7.2.2 | D22: 生活垃圾清运（按立方）
C23: 1.1.2.7.2.3 | D23: 生活垃圾清运（按户）
A24: 6401.03.02.10 | B24: 工程施工外包 | C24: 1.3 | D24: 维改成本
A25: 6401.03.02.11 | B25: 人事外包费 | C25: 1.1.1.1.2 | D25: 劳务派遣
C26: 1.1.1.2.2 | D26: 劳务派遣
C27: 1.1.1.3.2 | D27: 劳务派遣
C28: 1.1.1.4.2 | D28: 劳务派遣
C29: 1.1.1.5.2 | D29: 劳务派遣
C30: 1.1.1.6.2 | D30: 劳务派遣
C31: 1.1.1.7.2 | D31: 劳务派遣
C32: 1.1.1.8.2 | D32: 劳务派遣
A33: 6401.03.07 | B33: 业务支持费 | C33: 1.5.9 | D33: 业务招待费
A34: 6401.03.80 | B34: 能源成本类
A35: 6401.03.80.01 | B35: 水费 | C35: 1.4.1 | D35: 公共水费及相关费
A36: 6401.03.80.02 | B36: 电费 | C36: 1.4.2 | D36: 公共电费
A37: 6401.03.80.03 | B37: 暖气费 | C37: 1.4.4 | D37: 公共采暖费
A38: 6401.03.80.04 | B38: 燃气费 | C38: 1.4.3 | D38: 公共燃气费
A39: 6401.03.80.99 | B39: 其他能源成本 | C39: 1.4.5 | D39: 公共其他能源费
C40: 1.5.4 | D40: 物管能源费
...

Sheet 运营成本管理看板
B2: 运营成本管理看板
B3: 项目名称 | D3: ='1-1 项目基础信息'!#REF! -> #REF! | I3: 年度 | J3: 2025 | K3: 月度 | L3: 6 | M3: 月 | O3: 预算目标中主要人工人数情况
B4: 年度总目标成本 A（万元） | D4: ='2 过程管理表单'!H4/10000 -> 37.658692 | F4: 时间进度 月份/12 | H4: =L3/12 -> 0.5 | J4: =H4 -> 0.5 | K4: =1-J4 -> 0.5 | O4: 自有人数 合计 （人） | P4: =SUM(P6:P10) -> 20 | Q4: 派遣人数 合计 （人） | R4: =SUM(Q6:Q10) -> 20 | S4: 外包人数 合计 （人） | T4: =SUM(R6:R10) -> 24
B5: 月累总目标成本 B（万元） | D5: =INDEX('4主要费项费项月累成本使用情况'!C38:N38,MATCH($L$3&"月",表3_3[[#Headers],[1月]:[12月]],0))/10000 -> 21.263124 | F5: 年度使用率 C/A | H5: =D6/D4 -> 0.33442519 | J5: =H5 -> 0.33442519 | K5: =1-J5 -> 0.66557481 | P5: 自有 | Q5: 派遣 | R5: 外包
B6: 月累已发生成本 C（万元） | D6: =INDEX('4主要费项费项月累成本使用情况'!C39:N39,MATCH($L$3&"月",表3_3[[#Headers],[1月]:[12月]],0))/10000 -> 12.594015 | F6: 月累使用率 C/B | H6: =D6/D5 -> 0.59229374 | J6: =H6 -> 0.59229374 | K6: =1-J6 -> 0.40770626 | O6: 保安 | P6: ='1-2 人员岗位信息'!D7 -> 0 | Q6: ='1-2 人员岗位信息'!D8 -> 0 | R6: ='1-2 人员岗位信息'!D9 -> 0
B7: 二级费项【月累】 超成本数量 | D7: =INDEX('4主要费项费项月累成本使用情况'!C48:N48,MATCH($L$3&"月",表3_3[[#Headers],[1月]:[12月]],0)) -> 0 | E7: /6 | F7: 自有人工使用率 已发生/年度目标 | H7: =IFERROR(INDEX(自有人员计算表!C35:N35,MATCH($L$3&"月",自有人员计算表!C1:N1,0))/自有人员计算表!N37,"无目标值") -> 0 | J7: =H7 -> 0 | K7: =1-J7 -> 1 | O7: 保洁 | P7: ='1-2 人员岗位信息'!D71 -> 0 | Q7: ='1-2 人员岗位信息'!D72 -> 0 | R7: ='1-2 人员岗位信息'!D73 -> 3
B8: 三级费项【月累】 超成本数量 | D8: =INDEX(三级费项月累表格!C195:N195,MATCH($L$3&"月",表3_3[[#Headers],[1月]:[12月]],0)) -> 2 | E8: /456 | F8: 劳务派遣使用率 已发生/年度目标 | H8: =IFERROR(INDEX(劳务派遣统计表!C35:N35,MATCH($L$3&"月",劳务派遣统计表!C1:N1,0))/劳务派遣统计表!N37,"无目标值") -> 无目标值 | J8: =H8 -> 无目标值 | K8: =1-J8 -> #VALUE! | O8: 工程 | P8: ='1-2 人员岗位信息'!D115 -> 1 | Q8: ='1-2 人员岗位信息'!D116 -> 0 | R8: ='1-2 人员岗位信息'!D117 -> 0
B9: 主控费项【月累】 超成本数量 | D9: 35 | E9: /103 | F9: 劳务外包使用率 已发生/年度目标 | H9: =IFERROR(INDEX(劳务外包表!C47:N47,MATCH($L$3&"月",劳务外包表!C1:N1,0))/劳务外包表!N49,"无目标值") -> 0.52564384 | J9: =H9 -> 0.52564384 | K9: =1-J9 -> 0.47435616 | O9: 管家 | P9: ='1-2 人员岗位信息'!D155 -> 0 | Q9: ='1-2 人员岗位信息'!D156 -> 0 | R9: ='1-2 人员岗位信息'!D157 -> 0
B10: 已签约合同数量 （份） | D10: {=SUMPRODUCT((TEXT('2-2 引出数据_合同数据仓库'!$E:$E,"yyyymm")<=TEXT(DATE(2025,$L$3+1,0),"yyyymm"))*(('2-2 引出数据_合同数据仓库'!$C:$C="审核通过")))} -> 1 | F10: 金采易购下单量 （单） | H10: {=SUMPRODUCT(--(LEFT('2-1 采购订单物料明细表报表导出'!$K:$K,7)<>"")*--(LEFT('2-1 采购订单物料明细表报表导出'!$K:$K,7)<=TEXT(DATE(2025,$L$3,1),"yyyy-mm")))} -> 2 | J10: 报销单据数量 （笔） | L10: {=SUMPRODUCT((TEXT('2-3 引出列表'!$N:$N,"yyyymm")<=TEXT(DATE(2025,$L$3+1,0),"yyyymm"))*(('2-3 引出列表'!$L:$L="已审核")+('2-3 引出列表'!$L:$L="已付款")))} -> 0 | O10: 客服 | P10: ='1-2 人员岗位信息'!D35 -> 19 | Q10: ='1-2 人员岗位信息'!D36 -> 20 | R10: ='1-2 人员岗位信息'!D37 -> 21
B12: 1 月累成本使用情况
B25: 2 每月成本使用情况
B45: 3 主要费项费项月累成本使用情况
N46: 费项 编码 | O46: 费项 名称 | P46: 年度目标成本 （万元） | Q46: 月累目标成本（万元） | R46: 月累已发生（万元） | S46: 年度使用率 | T46: 月度使用率
N48: 1.1 | O48: 服务成本 | P48: ='2 过程管理表单'!H5/10000 -> 32.914692 | Q48: =INDEX('4主要费项费项月累成本使用情况'!C5:N5,MATCH($L$3&"月",表3_3[[#Headers],[1月]:[12月]],0))/10000 -> 16.759124 | R48: =INDEX('4主要费项费项月累成本使用情况'!C3:N3,MATCH($L$3&"月",表3_3[[#Headers],[1月]:[12月]],0))/10000 -> 12.594015 | S48: =IFERROR(R48/P48,"无年度目标") -> 0.38262595 | T48: =IFERROR(R48/Q48,"无月度目标") -> 0.75147217
N49: 1.2 | O49: 物耗成本 | P49: ='2 过程管理表单'!H508/10000 -> 4.2 | Q49: =INDEX('4主要费项费项月累成本使用情况'!C9:N9,MATCH($L$3&"月",表3_3[[#Headers],[1月]:[12月]],0))/10000 -> 4.2 | R49: =INDEX('4主要费项费项月累成本使用情况'!C7:N7,MATCH($L$3&"月",表3_3[[#Headers],[1月]:[12月]],0))/10000 -> 0 | S49: =IFERROR(R49/P49,"无年度目标") -> 0 | T49: =IFERROR(R49/Q49,"无月度目标") -> 0
N50: 1.3 | O50: 维改成本 | P50: ='2 过程管理表单'!H536/10000 -> 0 | Q50: =INDEX('4主要费项费项月累成本使用情况'!C13:N13,MATCH($L$3&"月",表3_3[[#Headers],[1月]:[12月]],0))/10000 -> 0 | R50: =INDEX('4主要费项费项月累成本使用情况'!C10:N10,MATCH($L$3&"月",表3_3[[#Headers],[1月]:[12月]],0))/10000 -> 0 | S50: =IFERROR(R50/P50,"无年度目标") -> 无年度目标 | T50: =IFERROR(R50/Q50,"无月度目标") -> 无月度目标
N51: 1.4 | O51: 能源成本 | P51: ='2 过程管理表单'!H597/10000 -> 0 | Q51: =INDEX('4主要费项费项月累成本使用情况'!C17:N17,MATCH($L$3&"月",表3_3[[#Headers],[1月]:[12月]],0))/10000 -> 0 | R51: =INDEX('4主要费项费项月累成本使用情况'!C15:N15,MATCH($L$3&"月",表3_3[[#Headers],[1月]:[12月]],0))/10000 -> 0 | S51: =IFERROR(R51/P51,"无年度目标") -> 无年度目标 | T51: =IFERROR(R51/Q51,"无月度目标") -> 无月度目标
N52: 1.5 | O52: 行政办公 | P52: ='2 过程管理表单'!H603/10000 -> 0.48 | Q52: =INDEX('4主要费项费项月累成本使用情况'!C21:N21,MATCH($L$3&"月",表3_3[[#Headers],[1月]:[12月]],0))/10000 -> 0.24 | R52: =INDEX('4主要费项费项月累成本使用情况'!C19:N19,MATCH($L$3&"月",表3_3[[#Headers],[1月]:[12月]],0))/10000 -> 0 | S52: =IFERROR(R52/P52,"无年度目标") -> 0 | T52: =IFERROR(R52/Q52,"无月度目标") -> 0
N53: 1.6 | O53: 前期投入 | P53: ='2 过程管理表单'!H616/10000 -> 0.064 | Q53: =INDEX('4主要费项费项月累成本使用情况'!C25:N25,MATCH($L$3&"月",表3_3[[#Headers],[1月]:[12月]],0))/10000 -> 0.064 | R53: =INDEX('4主要费项费项月累成本使用情况'!C23:N23,MATCH($L$3&"月",表3_3[[#Headers],[1月]:[12月]],0))/10000 -> 0 | S53: =IFERROR(R53/P53,"无年度目标") -> 0 | T53: =IFERROR(R53/Q53,"无月度目标") -> 0
N54: 1.1.1 | O54: 人工服务 | P54: ='2 过程管理表单'!H6/10000 -> 32.442994 | Q54: =INDEX('4主要费项费项月累成本使用情况'!C29:N29,MATCH($L$3&"月",表3_3[[#Headers],[1月]:[12月]],0))/10000 -> 16.287426 | R54: =INDEX('4主要费项费项月累成本使用情况'!C27:N27,MATCH($L$3&"月",表3_3[[#Headers],[1月]:[12月]],0))/10000 -> 11.544329 | S54: =IFERROR(R54/P54,"无年度目标") -> 0.35583426 | T54: =IFERROR(R54/Q54,"无月度目标") -> 0.70878779
N55: 1.1.2 | O55: 维护服务 | P55: ='2 过程管理表单'!H177/10000 -> 0.47169811 | Q55: =INDEX('4主要费项费项月累成本使用情况'!C33:N33,MATCH($L$3&"月",表3_3[[#Headers],[1月]:[12月]],0))/10000 -> 0 | R55: =INDEX('4主要费项费项月累成本使用情况'!C31:N31,MATCH($L$3&"月",表3_3[[#Headers],[1月]:[12月]],0))/10000 -> 0 | S55: =IFERROR(R55/P55,"无年度目标") -> 0 | T55: =IFERROR(R55/Q55,"无月度目标") -> 无月度目标
N56: 1.1.3 | O56: 检测服务 | P56: ='2 过程管理表单'!H428/10000 -> 0 | Q56: =INDEX('4主要费项费项月累成本使用情况'!C37:N37,MATCH($L$3&"月",表3_3[[#Headers],[1月]:[12月]],0))/10000 -> 0.47169811 | R56: =INDEX('4主要费项费项月累成本使用情况'!C35:N35,MATCH($L$3&"月",表3_3[[#Headers],[1月]:[12月]],0))/10000 -> 1.0496867 | S56: =IFERROR(R56/P56,"无年度目标") -> 无年度目标 | T56: =IFERROR(R56/Q56,"无月度目标") -> 2.2253357
L57: 0
B58: 4 二级费项目标成本每月使用情况
B71: 5 异常项统计表

Sheet 运营成本管理看板 (2)
B2: 运营成本管理看板
B3: 项目名称 | D3: ='1-1 项目基础信息'!D8 -> 深圳区域公司深圳市福田区梅华小学物业管理服务中心 | I3: 年度 | J3: 2025 | K3: 月度 | L3: 5 | M3: 月 | O3: 预算目标中主要人工人数情况
B4: 年度总目标成本 A（万元） | D4: ='2 过程管理表单'!H4/10000 -> 37.658692 | F4: 时间进度 月份/12 | H4: =L3/12 -> 0.41666667 | J4: =H4 -> 0.41666667 | K4: =1-J4 -> 0.58333333 | O4: 自有人数 合计 （人） | P4: =SUM(P6:P10) -> 20 | Q4: 派遣人数 合计 （人） | R4: =SUM(Q6:Q10) -> 20 | S4: 外包人数 合计 （人） | T4: =SUM(R6:R10) -> 24
B5: 月累总目标成本 B（万元） | D5: =INDEX('4-1主要费项费项月累成本使用情况 '!C38:N38,MATCH($L$3&"月",表3_3[[#Headers],[1月]:[12月]],0))/10000 -> 13.822642 | F5: 年度使用率 C/A | H5: =D6/D4 -> 0.27457455 | J5: =H5 -> 0.27457455 | K5: =1-J5 -> 0.72542545 | P5: 自有 | Q5: 派遣 | R5: 外包
B6: 月累已发生成本 C（万元） | D6: =INDEX('4-1主要费项费项月累成本使用情况 '!C39:N39,MATCH($L$3&"月",表3_3[[#Headers],[1月]:[12月]],0))/10000 -> 10.340118 | F6: 月累使用率 C/B | H6: =D6/D5 -> 0.74805662 | J6: =H6 -> 0.74805662 | K6: =1-J6 -> 0.25194338 | O6: 保安 | P6: ='1-2 人员岗位信息'!D7 -> 0 | Q6: ='1-2 人员岗位信息'!D8 -> 0 | R6: ='1-2 人员岗位信息'!D9 -> 0
B7: 二级费项【月累】 超成本数量 | D7: =INDEX('4-1主要费项费项月累成本使用情况 '!C48:N48,MATCH($L$3&"月",表3_3[[#Headers],[1月]:[12月]],0)) -> 0 | E7: /6 | F7: 自有人工使用率 已发生/年度目标 | H7: =IFERROR(INDEX(自有人员计算表!C35:N35,MATCH($L$3&"月",自有人员计算表!C1:N1,0))/自有人员计算表!N37,"无目标值") -> 0 | J7: =H7 -> 0 | K7: =1-J7 -> 1 | O7: 保洁 | P7: ='1-2 人员岗位信息'!D71 -> 0 | Q7: ='1-2 人员岗位信息'!D72 -> 0 | R7: ='1-2 人员岗位信息'!D73 -> 3
B8: 三级费项【月累】 超成本数量 | D8: =INDEX(三级费项月累表格!C195:N195,MATCH($L$3&"月",表3_3[[#Headers],[1月]:[12月]],0)) -> 1 | E8: /456 | F8: 劳务派遣使用率 已发生/年度目标 | H8: =IFERROR(INDEX(劳务派遣统计表!C35:N35,MATCH($L$3&"月",劳务派遣统计表!C1:N1,0))/劳务派遣统计表!N37,"无目标值") -> 无目标值 | J8: =H8 -> 无目标值 | K8: =1-J8 -> #VALUE! | O8: 工程 | P8: ='1-2 人员岗位信息'!D115 -> 1 | Q8: ='1-2 人员岗位信息'!D116 -> 0 | R8: ='1-2 人员岗位信息'!D117 -> 0
B9: 主控费项【月累】 超成本数量 | D9: =INDEX('4-1主要费项费项月累成本使用情况 '!C52:N52,MATCH($L$3&"月",表3_3[[#Headers],[1月]:[12月]],0)) -> 3 | E9: /103 | F9: 劳务外包使用率 已发生/年度目标 | H9: =IFERROR(INDEX(劳务外包表!C47:N47,MATCH($L$3&"月",劳务外包表!C1:N1,0))/劳务外包表!N49,"无目标值") -> 0.43852055 | J9: =H9 -> 0.43852055 | K9: =1-J9 -> 0.56147945 | O9: 管家 | P9: ='1-2 人员岗位信息'!D155 -> 0 | Q9: ='1-2 人员岗位信息'!D156 -> 0 | R9: ='1-2 人员岗位信息'!D157 -> 0
B10: 已签约合同数量 （份） | D10: {=SUMPRODUCT((TEXT('2-2 引出数据_合同数据仓库'!$E:$E,"yyyymm")<=TEXT(DATE(2025,$L$3+1,0),"yyyymm"))*(('2-2 引出数据_合同数据仓库'!$C:$C="审核通过")))} -> 0 | F10: 金采易购下单量 （单） | H10: {=SUMPRODUCT(--(LEFT('2-1 采购订单物料明细表报表导出'!$K:$K,7)<>"")*--(LEFT('2-1 采购订单物料明细表报表导出'!$K:$K,7)<=TEXT(DATE(2025,$L$3,1),"yyyy-mm")))} -> 1 | J10: 报销单据数量 （笔） | L10: {=SUMPRODUCT((TEXT('2-3 引出列表'!$N:$N,"yyyymm")<=TEXT(DATE(2025,$L$3+1,0),"yyyymm"))*(('2-3 引出列表'!$L:$L="已审核")+('2-3 引出列表'!$L:$L="已付款")))} -> 0 | O10: 客服 | P10: ='1-2 人员岗位信息'!D35 -> 19 | Q10: ='1-2 人员岗位信息'!D36 -> 20 | R10: ='1-2 人员岗位信息'!D37 -> 21
B12: 1 月累成本使用情况
B25: 2 每月成本使用情况
B45: 3 主要费项费项月累成本使用情况
N46: 费项 编码 | O46: 费项 名称 | P46: 年度目标成本 （万元） | Q46: 月累目标成本（万元） | R46: 月累已发生（万元） | S46: 年度使用率 | T46: 月度使用率
N48: 1.1 | O48: 服务成本 | P48: ='2 过程管理表单'!H5/10000 -> 32.914692 | Q48: =INDEX('4-1主要费项费项月累成本使用情况 '!C5:N5,MATCH($L$3&"月",表3_3[[#Headers],[1月]:[12月]],0))/10000 -> 9.6226415 | R48: =INDEX('4-1主要费项费项月累成本使用情况 '!C3:N3,MATCH($L$3&"月",表3_3[[#Headers],[1月]:[12月]],0))/10000 -> 10.340118 | S48: =IFERROR(R48/P48,"无年度目标") -> 0.31414903 | T48: =IFERROR(R48/Q48,"无月度目标") -> 1.0745613
N49: 1.2 | O49: 物耗成本 | P49: ='2 过程管理表单'!H508/10000 -> 4.2 | Q49: =INDEX('4-1主要费项费项月累成本使用情况 '!C9:N9,MATCH($L$3&"月",表3_3[[#Headers],[1月]:[12月]],0))/10000 -> 4.2 | R49: =INDEX('4-1主要费项费项月累成本使用情况 '!C7:N7,MATCH($L$3&"月",表3_3[[#Headers],[1月]:[12月]],0))/10000 -> 0 | S49: =IFERROR(R49/P49,"无年度目标") -> 0 | T49: =IFERROR(R49/Q49,"无月度目标") -> 0
N50: 1.3 | O50: 维改成本 | P50: ='2 过程管理表单'!H536/10000 -> 0 | Q50: =INDEX('4-1主要费项费项月累成本使用情况 '!C13:N13,MATCH($L$3&"月",表3_3[[#Headers],[1月]:[12月]],0))/10000 -> 0 | R50: =INDEX('4-1主要费项费项月累成本使用情况 '!C10:N10,MATCH($L$3&"月",表3_3[[#Headers],[1月]:[12月]],0))/10000 -> 0 | S50: =IFERROR(R50/P50,"无年度目标") -> 无年度目标 | T50: =IFERROR(R50/Q50,"无月度目标") -> 无月度目标
N51: 1.4 | O51: 能源成本 | P51: ='2 过程管理表单'!H598/10000 -> 0 | Q51: =INDEX('4-1主要费项费项月累成本使用情况 '!C17:N17,MATCH($L$3&"月",表3_3[[#Headers],[1月]:[12月]],0))/10000 -> 0 | R51: =INDEX('4-1主要费项费项月累成本使用情况 '!C15:N15,MATCH($L$3&"月",表3_3[[#Headers],[1月]:[12月]],0))/10000 -> 0 | S51: =IFERROR(R51/P51,"无年度目标") -> 无年度目标 | T51: =IFERROR(R51/Q51,"无月度目标") -> 无月度目标
N52: 1.5 | O52: 行政办公 | P52: ='2 过程管理表单'!H604/10000 -> 0 | Q52: =INDEX('4-1主要费项费项月累成本使用情况 '!C21:N21,MATCH($L$3&"月",表3_3[[#Headers],[1月]:[12月]],0))/10000 -> 0 | R52: =INDEX('4-1主要费项费项月累成本使用情况 '!C19:N19,MATCH($L$3&"月",表3_3[[#Headers],[1月]:[12月]],0))/10000 -> 0 | S52: =IFERROR(R52/P52,"无年度目标") -> 无年度目标 | T52: =IFERROR(R52/Q52,"无月度目标") -> 无月度目标
N53: 1.6 | O53: 前期投入 | P53: ='2 过程管理表单'!H617/10000 -> 0 | Q53: =INDEX('4-1主要费项费项月累成本使用情况 '!C25:N25,MATCH($L$3&"月",表3_3[[#Headers],[1月]:[12月]],0))/10000 -> 0 | R53: =INDEX('4-1主要费项费项月累成本使用情况 '!C23:N23,MATCH($L$3&"月",表3_3[[#Headers],[1月]:[12月]],0))/10000 -> 0 | S53: =IFERROR(R53/P53,"无年度目标") -> 无年度目标 | T53: =IFERROR(R53/Q53,"无月度目标") -> 无月度目标
N54: 1.1.1 | O54: 人工服务 | P54: ='2 过程管理表单'!H6/10000 -> 32.442994 | Q54: =INDEX('4-1主要费项费项月累成本使用情况 '!C29:N29,MATCH($L$3&"月",表3_3[[#Headers],[1月]:[12月]],0))/10000 -> 13.594831 | R54: =INDEX('4-1主要费项费项月累成本使用情况 '!C27:N27,MATCH($L$3&"月",表3_3[[#Headers],[1月]:[12月]],0))/10000 -> 9.6309041 | S54: =IFERROR(R54/P54,"无年度目标") -> 0.2968562 | T54: =IFERROR(R54/Q54,"无月度目标") -> 0.70842395
N55: 1.1.2 | O55: 维护服务 | P55: ='2 过程管理表单'!H177/10000 -> 0.47169811 | Q55: =INDEX('4-1主要费项费项月累成本使用情况 '!C33:N33,MATCH($L$3&"月",表3_3[[#Headers],[1月]:[12月]],0))/10000 -> 0 | R55: =INDEX('4-1主要费项费项月累成本使用情况 '!C31:N31,MATCH($L$3&"月",表3_3[[#Headers],[1月]:[12月]],0))/10000 -> 0 | S55: =IFERROR(R55/P55,"无年度目标") -> 0 | T55: =IFERROR(R55/Q55,"无月度目标") -> 无月度目标
N56: 1.1.3 | O56: 检测服务 | P56: ='2 过程管理表单'!H428/10000 -> 0 | Q56: =INDEX('4-1主要费项费项月累成本使用情况 '!C37:N37,MATCH($L$3&"月",表3_3[[#Headers],[1月]:[12月]],0))/10000 -> 0.47169811 | R56: =INDEX('4-1主要费项费项月累成本使用情况 '!C35:N35,MATCH($L$3&"月",表3_3[[#Headers],[1月]:[12月]],0))/10000 -> 0.70921439 | S56: =IFERROR(R56/P56,"无年度目标") -> 无年度目标 | T56: =IFERROR(R56/Q56,"无月度目标") -> 1.5035345
L57: 0
B58: 4 二级费项目标成本每月使用情况
B71: 5 异常项统计表

Sheet 预算主表
A1: 02经营数据明细表
A2: 科目编码 | B2: 科目名称 | C2: 2024年实际 | D2: 1月实际 | E2: 2月实际 | F2: 3月实际 | G2: 4月实际 | H2: 5月实际 | I2: 6月实际 | J2: 7月实际 | K2: 8月实际 | L2: 9月实际 | M2: 10月实际 | N2: 11月实际 | O2: 12月实际 | P2: 2025年预算 | Q2: 1月预算 | R2: 2月预算 | S2: 3月预算 | T2: 4月预算 | U2: 5月预算 | V2: 6月预算 | W2: 7月预算 | X2: 8月预算 | Y2: 9月预算 | Z2: 10月预算 | AA2: 11月预算 | AB2: 12月预算
A3: 6000 | B3: （一）营业收入 | C3: 437893.14 | D3: 36973.28 | E3: 36973.28 | F3: 36973.28 | G3: 36973.28 | H3: 36973.28 | I3: 36973.28 | J3: 36973.28 | K3: 36973.28 | L3: 36973.28 | M3: 36973.24 | N3: 34080.19 | O3: 34080.19 | P3: 408962.26 | Q3: 34080.189 | R3: 34080.189 | S3: 34080.189 | T3: 34080.189 | U3: 34080.189 | V3: 34080.189 | W3: 34080.189 | X3: 34080.189 | Y3: 34080.189 | Z3: 34080.189 | AA3: 34080.189 | AB3: 34080.189
A4: 6001 | B4: 主营业务收入 | C4: 437893.14 | D4: 36973.28 | E4: 36973.28 | F4: 36973.28 | G4: 36973.28 | H4: 36973.28 | I4: 36973.28 | J4: 36973.28 | K4: 36973.28 | L4: 36973.28 | M4: 36973.24 | N4: 34080.19 | O4: 34080.19 | P4: 408962.26 | Q4: 34080.189 | R4: 34080.189 | S4: 34080.189 | T4: 34080.189 | U4: 34080.189 | V4: 34080.189 | W4: 34080.189 | X4: 34080.189 | Y4: 34080.189 | Z4: 34080.189 | AA4: 34080.189 | AB4: 34080.189
A5: 6001.03 | B5: 物业管理业务收入 | C5: 437893.14 | D5: 36973.28 | E5: 36973.28 | F5: 36973.28 | G5: 36973.28 | H5: 36973.28 | I5: 36973.28 | J5: 36973.28 | K5: 36973.28 | L5: 36973.28 | M5: 36973.24 | N5: 34080.19 | O5: 34080.19 | P5: 408962.26 | Q5: 34080.189 | R5: 34080.189 | S5: 34080.189 | T5: 34080.189 | U5: 34080.189 | V5: 34080.189 | W5: 34080.189 | X5: 34080.189 | Y5: 34080.189 | Z5: 34080.189 | AA5: 34080.189 | AB5: 34080.189
A6: 6001.03.01 | B6: 物业服务 | C6: 437893.14 | D6: 36973.28 | E6: 36973.28 | F6: 36973.28 | G6: 36973.28 | H6: 36973.28 | I6: 36973.28 | J6: 36973.28 | K6: 36973.28 | L6: 36973.28 | M6: 36973.24 | N6: 34080.19 | O6: 34080.19 | P6: 408962.26 | Q6: 34080.189 | R6: 34080.189 | S6: 34080.189 | T6: 34080.189 | U6: 34080.189 | V6: 34080.189 | W6: 34080.189 | X6: 34080.189 | Y6: 34080.189 | Z6: 34080.189 | AA6: 34080.189 | AB6: 34080.189
A7: 6001.03.01.01 | B7: 项目物业服务费款 | C7: 431289.34 | D7: 36973.28 | E7: 36973.28 | F7: 36973.28 | G7: 36029.88 | H7: 36029.88 | I7: 36029.88 | J7: 36029.88 | K7: 36029.88 | L7: 36029.88 | M7: 36029.84 | N7: 34080.19 | O7: 34080.19 | P7: 408962.26 | Q7: 34080.189 | R7: 34080.189 | S7: 34080.189 | T7: 34080.189 | U7: 34080.189 | V7: 34080.189 | W7: 34080.189 | X7: 34080.189 | Y7: 34080.189 | Z7: 34080.189 | AA7: 34080.189 | AB7: 34080.189
A8: 6001.03.01.02 | B8: 车位服务费收入 | C8: 0 | P8: 0 | Q8: 0 | R8: 0 | S8: 0 | T8: 0 | U8: 0 | V8: 0 | W8: 0 | X8: 0 | Y8: 0 | Z8: 0 | AA8: 0 | AB8: 0
A9: 6001.03.01.03 | B9: 车位租赁费收入 | C9: 0 | P9: 0 | Q9: 0 | R9: 0 | S9: 0 | T9: 0 | U9: 0 | V9: 0 | W9: 0 | X9: 0 | Y9: 0 | Z9: 0 | AA9: 0 | AB9: 0
A10: 6001.03.01.04 | B10: 公共资源经营收益 | C10: 0 | P10: 0 | Q10: 0 | R10: 0 | S10: 0 | T10: 0 | U10: 0 | V10: 0 | W10: 0 | X10: 0 | Y10: 0 | Z10: 0 | AA10: 0 | AB10: 0
A11: 6001.03.01.05 | B11: 设备设施使用费收入 | C11: 0 | P11: 0
A12: 6001.03.01.06 | B12: 项目酬金收入 | C12: 0 | P12: 0
A13: 6001.03.01.07 | B13: 代销能源收入 | C13: 0 | D13: 0 | E13: 0 | F13: 0 | G13: 0 | H13: 0 | I13: 0 | J13: 0 | K13: 0 | L13: 0 | M13: 0 | N13: 0 | O13: 0 | P13: 0 | Q13: 0 | R13: 0 | S13: 0 | T13: 0 | U13: 0 | V13: 0 | W13: 0 | X13: 0 | Y13: 0 | Z13: 0 | AA13: 0 | AB13: 0
A14: 6001.03.01.07.01 | B14: 供水收入 | C14: 0 | P14: 0
A15: 6001.03.01.07.02 | B15: 供电收入 | C15: 0 | P15: 0
A16: 6001.03.01.07.03 | B16: 暖气收入 | C16: 0 | P16: 0
A17: 6001.03.01.07.04 | B17: 燃气收入 | C17: 0 | P17: 0
A18: 6001.03.01.07.99 | B18: 其他代销能源收入 | C18: 0 | P18: 0
A19: 6001.03.01.99 | B19: 其他物业服务收入 | C19: 6603.8 | D19: 0 | E19: 0 | F19: 0 | G19: 943.4 | H19: 943.4 | I19: 943.4 | J19: 943.4 | K19: 943.4 | L19: 943.4 | M19: 943.4 | P19: 0 | Q19: 0 | R19: 0 | S19: 0 | T19: 0 | U19: 0 | V19: 0 | W19: 0 | X19: 0 | Y19: 0 | Z19: 0 | AA19: 0 | AB19: 0
A20: 6001.03.02 | B20: 前期物业服务 | C20: 0 | D20: 0 | E20: 0 | F20: 0 | G20: 0 | H20: 0 | I20: 0 | J20: 0 | K20: 0 | L20: 0 | M20: 0 | N20: 0 | O20: 0 | P20: 0 | Q20: 0 | R20: 0 | S20: 0 | T20: 0 | U20: 0 | V20: 0 | W20: 0 | X20: 0 | Y20: 0 | Z20: 0 | AA20: 0 | AB20: 0
A21: 6001.03.02.01 | B21: 项目案场服务收入 | C21: 0 | P21: 0 | Q21: 0 | R21: 0 | S21: 0 | T21: 0 | U21: 0 | V21: 0 | W21: 0 | X21: 0 | Y21: 0 | Z21: 0 | AA21: 0 | AB21: 0
A22: 6001.03.02.02 | B22: 开办费收入 | C22: 0 | P22: 0 | Q22: 0 | R22: 0 | S22: 0 | T22: 0 | U22: 0 | V22: 0 | W22: 0 | X22: 0 | Y22: 0 | Z22: 0 | AA22: 0 | AB22: 0
A23: 6001.03.02.99 | B23: 其他前期物业服务收入 | C23: 0 | P23: 0 | Q23: 0 | R23: 0 | S23: 0 | T23: 0 | U23: 0 | V23: 0 | W23: 0 | X23: 0 | Y23: 0 | Z23: 0 | AA23: 0 | AB23: 0
A24: 6001.03.03 | B24: 社区商业 | C24: 0 | D24: 0 | E24: 0 | F24: 0 | G24: 0 | H24: 0 | I24: 0 | J24: 0 | K24: 0 | L24: 0 | M24: 0 | N24: 0 | O24: 0 | P24: 0 | Q24: 0 | R24: 0 | S24: 0 | T24: 0 | U24: 0 | V24: 0 | W24: 0 | X24: 0 | Y24: 0 | Z24: 0 | AA24: 0 | AB24: 0
A25: 6001.03.03.01 | B25: 自营商品销售收入 | C25: 0 | P25: 0 | Q25: 0 | R25: 0 | S25: 0 | T25: 0 | U25: 0 | V25: 0 | W25: 0 | X25: 0 | Y25: 0 | Z25: 0 | AA25: 0 | AB25: 0
A26: 6001.03.03.02 | B26: 自营生活服务收入 | C26: 0 | P26: 0 | Q26: 0 | R26: 0 | S26: 0 | T26: 0 | U26: 0 | V26: 0 | W26: 0 | X26: 0 | Y26: 0 | Z26: 0 | AA26: 0 | AB26: 0
A27: 6001.03.03.03 | B27: 平台佣金收入 | C27: 0 | P27: 0 | Q27: 0 | R27: 0 | S27: 0 | T27: 0 | U27: 0 | V27: 0 | W27: 0 | X27: 0 | Y27: 0 | Z27: 0 | AA27: 0 | AB27: 0
A28: 6001.03.04 | B28: 房屋配套升级款 | C28: 0 | D28: 0 | E28: 0 | F28: 0 | G28: 0 | H28: 0 | I28: 0 | J28: 0 | K28: 0 | L28: 0 | M28: 0 | N28: 0 | O28: 0 | P28: 0 | Q28: 0 | R28: 0 | S28: 0 | T28: 0 | U28: 0 | V28: 0 | W28: 0 | X28: 0 | Y28: 0 | Z28: 0 | AA28: 0 | AB28: 0
A29: 6001.03.04.01 | B29: 自营业务收入 | C29: 0 | P29: 0 | Q29: 0 | R29: 0 | S29: 0 | T29: 0 | U29: 0 | V29: 0 | W29: 0 | X29: 0 | Y29: 0 | Z29: 0 | AA29: 0 | AB29: 0
A30: 6001.03.04.02 | B30: 平台佣金收入 | C30: 0 | P30: 0 | Q30: 0 | R30: 0 | S30: 0 | T30: 0 | U30: 0 | V30: 0 | W30: 0 | X30: 0 | Y30: 0 | Z30: 0 | AA30: 0 | AB30: 0
A31: 6001.03.05 | B31: 房屋增值维修款 | C31: 0 | D31: 0 | E31: 0 | F31: 0 | G31: 0 | H31: 0 | I31: 0 | J31: 0 | K31: 0 | L31: 0 | M31: 0 | N31: 0 | O31: 0 | P31: 0 | Q31: 0 | R31: 0 | S31: 0 | T31: 0 | U31: 0 | V31: 0 | W31: 0 | X31: 0 | Y31: 0 | Z31: 0 | AA31: 0 | AB31: 0
A32: 6001.03.05.01 | B32: 自营维修业务收入 | C32: 0 | P32: 0 | Q32: 0 | R32: 0 | S32: 0 | T32: 0 | U32: 0 | V32: 0 | W32: 0 | X32: 0 | Y32: 0 | Z32: 0 | AA32: 0 | AB32: 0
A33: 6001.03.05.02 | B33: 联营维修业务收入 | C33: 0 | P33: 0 | Q33: 0 | R33: 0 | S33: 0 | T33: 0 | U33: 0 | V33: 0 | W33: 0 | X33: 0 | Y33: 0 | Z33: 0 | AA33: 0 | AB33: 0
A34: 6001.03.06 | B34: 城市物业服务 | C34: 0 | D34: 0 | E34: 0 | F34: 0 | G34: 0 | H34: 0 | I34: 0 | J34: 0 | K34: 0 | L34: 0 | M34: 0 | N34: 0 | O34: 0 | P34: 0 | Q34: 0 | R34: 0 | S34: 0 | T34: 0 | U34: 0 | V34: 0 | W34: 0 | X34: 0 | Y34: 0 | Z34: 0 | AA34: 0 | AB34: 0
A35: 6001.03.06.01 | B35: 保洁服务收入 | C35: 0 | P35: 0
A36: 6001.03.06.02 | B36: 环卫服务收入 | C36: 0 | P36: 0
A37: 6001.03.06.03 | B37: 其他城市服务收入 | C37: 0 | P37: 0
A38: 6001.03.07 | B38: 家政服务 | C38: 0 | D38: 0 | E38: 0 | F38: 0 | G38: 0 | H38: 0 | I38: 0 | J38: 0 | K38: 0 | L38: 0 | M38: 0 | N38: 0 | O38: 0 | P38: 0 | Q38: 0 | R38: 0 | S38: 0 | T38: 0 | U38: 0 | V38: 0 | W38: 0 | X38: 0 | Y38: 0 | Z38: 0 | AA38: 0 | AB38: 0
A39: 6001.03.07.01 | B39: 保洁服务收入 | C39: 0 | P39: 0
A40: 6001.03.07.02 | B40: 洗衣服务收入 | C40: 0 | P40: 0
...

Sheet 自有人工预算
A1: Kingdee | B1: JDC001-7.1 | C1: 自有人工预算
B2: 组织 | C2: WY.SZ | D2: 深圳物业公司
B3: 版本 | C3: VNone | D3: 不区分版本
B4: 预算期间 | C4: 2025年
B5: 填报单位名称 | C5: 梅华小学 | D5: 项目荟系列档位
B7: 01.人数信息
B8: 岗位 | C8: 人力维度 | D8: 2025年预算 | E8: 1月预算 | F8: 2月预算 | G8: 3月预算 | H8: 4月预算 | I8: 5月预算 | J8: 6月预算 | K8: 7月预算 | L8: 8月预算 | M8: 9月预算 | N8: 10月预算 | O8: 11月预算 | P8: 12月预算 | Q8: 荟系列标准用工形式 | R8: 25年用工形式 | S8: 差异说明 | T8: 荟系列标准编制 | U8: 25年编制 | V8: 差异说明
B9: 管理及专业序列 | C9: 非技能 | D9: 0
B10: 工程 | C10: 工程管理 | D10: 1 | E10: 1 | F10: 1 | G10: 1 | H10: 1 | I10: 1 | J10: 1 | K10: 1 | L10: 1 | M10: 1 | N10: 1 | O10: 1 | P10: 1
B11: 安全 | C11: 安全管理 | D11: 0
B12: 环境 | C12: 环境管理 | D12: 0
B13: 客服 | C13: 客服管理 | D13: 0
B14: 其他 | C14: 项目其他 | D14: 0
B15: 片总 | C15: 片总 | D15: 0
B16: 运营经理 | C16: 运营经理 | D16: 0
B17: 人力BP | C17: 人力BP | D17: 0
B18: 财务BP | C18: 财务BP | D18: 0
B19: 其他 | C19: 其他 | D19: 0
B20: 汇总 | D20: 1 | E20: 1 | F20: 1 | G20: 1 | H20: 1 | I20: 1 | J20: 1 | K20: 1 | L20: 1 | M20: 1 | N20: 1 | O20: 1 | P20: 1
B22: 02.人工总成本
B23: 岗位 | C23: 人力维度 | D23: 2025年预算 | E23: 1月预算 | F23: 2月预算 | G23: 3月预算 | H23: 4月预算 | I23: 5月预算 | J23: 6月预算 | K23: 7月预算 | L23: 8月预算 | M23: 9月预算 | N23: 10月预算 | O23: 11月预算 | P23: 12月预算
B24: 管理及专业序列 | C24: 非技能 | D24: 0 | E24: 0 | F24: 0 | G24: 0 | H24: 0 | I24: 0 | J24: 0 | K24: 0 | L24: 0 | M24: 0 | N24: 0 | O24: 0 | P24: 0
B25: 工程 | C25: 工程管理 | D25: 104807.3 | E25: 9942.64 | F25: 8624.06 | G25: 8624.06 | H25: 8624.06 | I25: 8624.06 | J25: 8624.06 | K25: 8624.06 | L25: 8624.06 | M25: 8624.06 | N25: 8624.06 | O25: 8624.06 | P25: 8624.06
B26: 安全 | C26: 安全管理 | D26: 0 | E26: 0 | F26: 0 | G26: 0 | H26: 0 | I26: 0 | J26: 0 | K26: 0 | L26: 0 | M26: 0 | N26: 0 | O26: 0 | P26: 0
B27: 环境 | C27: 环境管理 | D27: 0 | E27: 0 | F27: 0 | G27: 0 | H27: 0 | I27: 0 | J27: 0 | K27: 0 | L27: 0 | M27: 0 | N27: 0 | O27: 0 | P27: 0
B28: 客服 | C28: 客服管理 | D28: 0 | E28: 0 | F28: 0 | G28: 0 | H28: 0 | I28: 0 | J28: 0 | K28: 0 | L28: 0 | M28: 0 | N28: 0 | O28: 0 | P28: 0
B29: 其他 | C29: 项目其他 | D29: 0 | E29: 0 | F29: 0 | G29: 0 | H29: 0 | I29: 0 | J29: 0 | K29: 0 | L29: 0 | M29: 0 | N29: 0 | O29: 0 | P29: 0
B30: 片总 | C30: 片总 | D30: 0 | E30: 0 | F30: 0 | G30: 0 | H30: 0 | I30: 0 | J30: 0 | K30: 0 | L30: 0 | M30: 0 | N30: 0 | O30: 0 | P30: 0
B31: 运营经理 | C31: 运营经理 | D31: 0 | E31: 0 | F31: 0 | G31: 0 | H31: 0 | I31: 0 | J31: 0 | K31: 0 | L31: 0 | M31: 0 | N31: 0 | O31: 0 | P31: 0
B32: 人力BP | C32: 人力BP | D32: 0 | E32: 0 | F32: 0 | G32: 0 | H32: 0 | I32: 0 | J32: 0 | K32: 0 | L32: 0 | M32: 0 | N32: 0 | O32: 0 | P32: 0
B33: 财务BP | C33: 财务BP | D33: 0 | E33: 0 | F33: 0 | G33: 0 | H33: 0 | I33: 0 | J33: 0 | K33: 0 | L33: 0 | M33: 0 | N33: 0 | O33: 0 | P33: 0
B34: 其他 | C34: 其他 | D34: 0 | E34: 0 | F34: 0 | G34: 0 | H34: 0 | I34: 0 | J34: 0 | K34: 0 | L34: 0 | M34: 0 | N34: 0 | O34: 0 | P34: 0
B35: 汇总 | D35: 104807.3 | E35: 9942.64 | F35: 8624.06 | G35: 8624.06 | H35: 8624.06 | I35: 8624.06 | J35: 8624.06 | K35: 8624.06 | L35: 8624.06 | M35: 8624.06 | N35: 8624.06 | O35: 8624.06 | P35: 8624.06
B37: 03.工资成本
B38: 岗位 | C38: 人力维度 | D38: 2025年预算 | E38: 1月预算 | F38: 2月预算 | G38: 3月预算 | H38: 4月预算 | I38: 5月预算 | J38: 6月预算 | K38: 7月预算 | L38: 8月预算 | M38: 9月预算 | N38: 10月预算 | O38: 11月预算 | P38: 12月预算
B39: 管理及专业序列 | C39: 非技能 | D39: 0
B40: 工程 | C40: 工程管理 | D40: 93240.48 | E40: 7770.04 | F40: 7770.04 | G40: 7770.04 | H40: 7770.04 | I40: 7770.04 | J40: 7770.04 | K40: 7770.04 | L40: 7770.04 | M40: 7770.04 | N40: 7770.04 | O40: 7770.04 | P40: 7770.04
B41: 安全 | C41: 安全管理 | D41: 0
B42: 环境 | C42: 环境管理 | D42: 0
B43: 客服 | C43: 客服管理 | D43: 0
...

Sheet 1 预算编制表单
A1: 合同维度 | B1: 是否为末级科目 | C1: 基础信息 | H1: 2025年 | O1: 填选发生月份 | AB1: 2025年 | AC1: 2025年 | AF1: 2025年 | AI1: 2025年 | AL1: 2025年 | AO1: 2025年 | AR1: 2025年 | AU1: 2025年 | AX1: 2025年 | BA1: 2025年 | BD1: 2025年 | BG1: 2025年 | BJ1: 2025年
AC2: 1月 | AF2: 2月 | AI2: 3月 | AL2: 4月 | AM2: 4月 | AN2: 4月 | AO2: 5月 | AP2: 5月 | AQ2: 5月 | AR2: 6月 | AS2: 6月 | AT2: 6月 | AU2: 7月 | AV2: 7月 | AW2: 7月 | AX2: 8月 | AY2: 8月 | AZ2: 8月 | BA2: 9月 | BB2: 9月 | BC2: 9月 | BD2: 10月 | BE2: 10月 | BF2: 10月 | BG2: 11月 | BH2: 11月 | BI2: 11月 | BJ2: 12月 | BK2: 12月 | BL2: 12月
C3: 费项编码 | D3: 费项名称 | E3: 指标说明 | F3: 填写说明 | G3: 编制周期& 分摊方式 | H3: 年总计 D=A*B*C | I3: 工程量说明 | J3: 工程量 A | K3: 计量单位 | L3: 单价 B | M3: 计价单位 | N3: 频次 C | O3: 1月 | P3: 2月 | Q3: 3月 | R3: 4月 | S3: 5月 | T3: 6月 | U3: 7月 | V3: 8月 | W3: 9月 | X3: 10月 | Y3: 11月 | Z3: 12月 | AA3: D-E | AB3: 1~12月合计 E | AC3: 总价 c=a*b | AD3: 工程量 a | AE3: 单价 b | AF3: 总价 c=a*b | AG3: 工程量 a | AH3: 单价 b | AI3: 总价 c=a*b | AJ3: 工程量 a | AK3: 单价 b | AL3: 总价 c=a*b | AM3: 工程量 a | AN3: 单价 b | AO3: 总价 c=a*b | AP3: 工程量 a | AQ3: 单价 b | AR3: 总价 c=a*b | AS3: 工程量 a | AT3: 单价 b | AU3: 总价 c=a*b | AV3: 工程量 a | AW3: 单价 b | AX3: 总价 c=a*b | AY3: 工程量 a | AZ3: 单价 b | BA3: 总价 c=a*b | BB3: 工程量 a | BC3: 单价 b | BD3: 总价 c=a*b | BE3: 工程量 a | BF3: 单价 b | BG3: 总价 c=a*b | BH3: 工程量 a | BI3: 单价 b | BJ3: 总价 c=a*b | BK3: 工程量 a | BL3: 单价 b
B4: 否 | C4: 1 | D4: 项目运营成本 | E4: 项目运营成本包含范围为项目，全部人员成本（含片区总及项目自有人员成本、项目团队行政费用等） | H4: =H5+H381+H582+H652+H658+H668 -> 376586.92 | AB4: =AB5+AB381+AB582+AB652+AB658+AB668 -> 376586.92 | AC4: =AC5+AC381+AC582+AC652+AC658+AC668 -> 76001.508 | AF4: =AF5+AF381+AF582+AF652+AF658+AF668 -> 27325.947 | AI4: =AI5+AI381+AI582+AI652+AI658+AI668 -> 27325.947 | AL4: =AL5+AL381+AL582+AL652+AL658+AL668 -> 27325.947 | AO4: =AO5+AO381+AO582+AO652+AO658+AO668 -> 27325.947 | AR4: =AR5+AR381+AR582+AR652+AR658+AR668 -> 27325.947 | AU4: =AU5+AU381+AU582+AU652+AU658+AU668 -> 27325.947 | AX4: =AX5+AX381+AX582+AX652+AX658+AX668 -> 27325.947 | BA4: =BA5+BA381+BA582+BA652+BA658+BA668 -> 27325.947 | BD4: =BD5+BD381+BD582+BD652+BD658+BD668 -> 27325.947 | BG4: =BG5+BG381+BG582+BG652+BG658+BG668 -> 27325.947 | BJ4: =BJ5+BJ381+BJ582+BJ652+BJ658+BJ668 -> 27325.947
B5: 否 | C5: 1.1 | D5: 服务成本 | H5: =H6+H208+H308 -> 329146.92 | AB5: =AB6+AB208+AB308 -> 329146.92 | AC5: =AC6+AC208+AC308 -> 32961.508 | AF5: =AF6+AF208+AF308 -> 26925.947 | AI5: =AI6+AI208+AI308 -> 26925.947 | AL5: =AL6+AL208+AL308 -> 26925.947 | AO5: =AO6+AO208+AO308 -> 26925.947 | AR5: =AR6+AR208+AR308 -> 26925.947 | AU5: =AU6+AU208+AU308 -> 26925.947 | AX5: =AX6+AX208+AX308 -> 26925.947 | BA5: =BA6+BA208+BA308 -> 26925.947 | BD5: =BD6+BD208+BD308 -> 26925.947 | BG5: =BG6+BG208+BG308 -> 26925.947 | BJ5: =BJ6+BJ208+BJ308 -> 26925.947
B6: 否 | C6: 1.1.1 | D6: 人工服务 | H6: =H7+H29+H57+H111+H143+H159+H176+H189 -> 324429.94 | AB6: =AB7+AB29+AB57+AB111+AB143+AB159+AB176+AB189 -> 324429.94 | AC6: =AC7+AC29+AC57+AC111+AC143+AC159+AC176+AC189 -> 28244.527 | AF6: =AF7+AF29+AF57+AF111+AF143+AF159+AF176+AF189 -> 26925.947 | AI6: =AI7+AI29+AI57+AI111+AI143+AI159+AI176+AI189 -> 26925.947 | AL6: =AL7+AL29+AL57+AL111+AL143+AL159+AL176+AL189 -> 26925.947 | AO6: =AO7+AO29+AO57+AO111+AO143+AO159+AO176+AO189 -> 26925.947 | AR6: =AR7+AR29+AR57+AR111+AR143+AR159+AR176+AR189 -> 26925.947 | AU6: =AU7+AU29+AU57+AU111+AU143+AU159+AU176+AU189 -> 26925.947 | AX6: =AX7+AX29+AX57+AX111+AX143+AX159+AX176+AX189 -> 26925.947 | BA6: =BA7+BA29+BA57+BA111+BA143+BA159+BA176+BA189 -> 26925.947 | BD6: =BD7+BD29+BD57+BD111+BD143+BD159+BD176+BD189 -> 26925.947 | BG6: =BG7+BG29+BG57+BG111+BG143+BG159+BG176+BG189 -> 26925.947 | BJ6: =BJ7+BJ29+BJ57+BJ111+BJ143+BJ159+BJ176+BJ189 -> 26925.947
B7: 否 | C7: 1.1.1.1 | D7: 保安人员 | H7: =H8+H15+H22 -> 0 | AB7: =AB8+AB15+AB22 -> 0 | AC7: =AC8+AC15+AC22 -> 0 | AF7: =AF8+AF15+AF22 -> 0 | AI7: =AI8+AI15+AI22 -> 0 | AL7: =AL8+AL15+AL22 -> 0 | AO7: =AO8+AO15+AO22 -> 0 | AR7: =AR8+AR15+AR22 -> 0 | AU7: =AU8+AU15+AU22 -> 0 | AX7: =AX8+AX15+AX22 -> 0 | BA7: =BA8+BA15+BA22 -> 0 | BD7: =BD8+BD15+BD22 -> 0 | BG7: =BG8+BG15+BG22 -> 0 | BJ7: =BJ8+BJ15+BJ22 -> 0
B8: 否 | C8: 1.1.1.1.1 | D8: 自有人员 | H8: =SUM(H9:H14) -> 0 | AB8: =SUM(AB9:AB14) -> 0 | AC8: =SUM(AC9:AC14) -> 0 | AF8: =SUM(AF9:AF14) -> 0 | AI8: =SUM(AI9:AI14) -> 0 | AL8: =SUM(AL9:AL14) -> 0 | AO8: =SUM(AO9:AO14) -> 0 | AR8: =SUM(AR9:AR14) -> 0 | AU8: =SUM(AU9:AU14) -> 0 | AX8: =SUM(AX9:AX14) -> 0 | BA8: =SUM(BA9:BA14) -> 0 | BD8: =SUM(BD9:BD14) -> 0 | BG8: =SUM(BG9:BG14) -> 0 | BJ8: =SUM(BJ9:BJ14) -> 0
B9: 是 | C9: 1.1.1.1.1.1 | D9: 保安经理 | E9: 指自有保安经理 | G9: 按月编制，汇总成年总量 | H9: =AB9 -> 0 | I9: 岗位数量 | J9: =SUM(AD9,AG9,AJ9,AM9,AP9,AS9,AV9,AY9,BB9,BE9,BH9,BK9)/N9 -> #DIV/0! | K9: 岗 | L9: =H9/N9/J9 -> #DIV/0! | M9: 元/㎡/月 | N9: =COUNTIF(AD9,">0")+COUNTIF(AG9,">0")+COUNTIF(AJ9,">0")+COUNTIF(AM9,">0")+COUNTIF(AP9,">0")+COUNTIF(AS9,">0")+COUNTIF(AV9,">0")+COUNTIF(AY9,">0")+COUNTIF(BB9,">0")+COUNTIF(BE9,">0")+COUNTIF(BH9,">0")+COUNTIF(BK9,">0") -> 0 | AB9: =SUM(AC9,AF9,AI9,AL9,AO9,AR9,AU9,AX9,BA9,BD9,BG9,BJ9) -> 0 | AC9: =AD9*AE9 -> 0 | AD9: ='1-2 人员岗位信息'!F11 -> 0 | AE9: =IFERROR(自有人工预算!E26/AD9,0) -> 0 | AF9: =AG9*AH9 -> 0 | AG9: =SUMIFS('1-2 人员岗位信息'!G:G,'1-2 人员岗位信息'!$C:$C,"自有人员",'1-2 人员岗位信息'!$B:$B,$D9) -> 0 | AH9: =IFERROR(自有人工预算!F26/AG9,0) -> 0 | AI9: =AJ9*AK9 -> 0 | AJ9: =SUMIFS('1-2 人员岗位信息'!H:H,'1-2 人员岗位信息'!$C:$C,"自有人员",'1-2 人员岗位信息'!$B:$B,$D9) -> 0 | AK9: =IFERROR(自有人工预算!G26/AJ9,0) -> 0 | AL9: =AM9*AN9 -> 0 | AM9: =SUMIFS('1-2 人员岗位信息'!I:I,'1-2 人员岗位信息'!$C:$C,"自有人员",'1-2 人员岗位信息'!$B:$B,$D9) -> 0 | AN9: =IFERROR(自有人工预算!H26/AM9,0) -> 0 | AO9: =AP9*AQ9 -> 0 | AP9: =SUMIFS('1-2 人员岗位信息'!J:J,'1-2 人员岗位信息'!$C:$C,"自有人员",'1-2 人员岗位信息'!$B:$B,$D9) -> 0 | AQ9: =IFERROR(自有人工预算!I26/AP9,0) -> 0 | AR9: =AS9*AT9 -> 0 | AS9: =SUMIFS('1-2 人员岗位信息'!K:K,'1-2 人员岗位信息'!$C:$C,"自有人员",'1-2 人员岗位信息'!$B:$B,$D9) -> 0 | AT9: =IFERROR(自有人工预算!J26/AS9,0) -> 0 | AU9: =AV9*AW9 -> 0 | AV9: =SUMIFS('1-2 人员岗位信息'!L:L,'1-2 人员岗位信息'!$C:$C,"自有人员",'1-2 人员岗位信息'!$B:$B,$D9) -> 0 | AW9: =IFERROR(自有人工预算!K26/AV9,0) -> 0 | AX9: =AY9*AZ9 -> 0 | AY9: =SUMIFS('1-2 人员岗位信息'!M:M,'1-2 人员岗位信息'!$C:$C,"自有人员",'1-2 人员岗位信息'!$B:$B,$D9) -> 0 | AZ9: =IFERROR(自有人工预算!L26/AY9,0) -> 0 | BA9: =BB9*BC9 -> 0 | BB9: =SUMIFS('1-2 人员岗位信息'!N:N,'1-2 人员岗位信息'!$C:$C,"自有人员",'1-2 人员岗位信息'!$B:$B,$D9) -> 0 | BC9: =IFERROR(自有人工预算!M26/BB9,0) -> 0 | BD9: =BE9*BF9 -> 0 | BE9: =SUMIFS('1-2 人员岗位信息'!O:O,'1-2 人员岗位信息'!$C:$C,"自有人员",'1-2 人员岗位信息'!$B:$B,$D9) -> 0 | BF9: =IFERROR(自有人工预算!N26/BE9,0) -> 0 | BG9: =BH9*BI9 -> 0 | BH9: =SUMIFS('1-2 人员岗位信息'!P:P,'1-2 人员岗位信息'!$C:$C,"自有人员",'1-2 人员岗位信息'!$B:$B,$D9) -> 0 | BI9: =IFERROR(自有人工预算!O26/BH9,0) -> 0 | BJ9: =BK9*BL9 -> 0 | BK9: =SUMIFS('1-2 人员岗位信息'!Q:Q,'1-2 人员岗位信息'!$C:$C,"自有人员",'1-2 人员岗位信息'!$B:$B,$D9) -> 0 | BL9: =IFERROR(自有人工预算!P26/BK9,0) -> 0
B10: 是 | C10: 1.1.1.1.1.2 | D10: 保安主管 | E10: 指自有保安主管 | G10: 按月编制，汇总成年总量 | H10: =AB10 -> 0 | I10: 岗位数量 | J10: =SUM(AD10,AG10,AJ10,AM10,AP10,AS10,AV10,AY10,BB10,BE10,BH10,BK10)/N10 -> #DIV/0! | K10: 岗 | L10: =H10/N10/J10 -> #DIV/0! | M10: 元/㎡/月 | N10: =COUNTIF(AD10,">0")+COUNTIF(AG10,">0")+COUNTIF(AJ10,">0")+COUNTIF(AM10,">0")+COUNTIF(AP10,">0")+COUNTIF(AS10,">0")+COUNTIF(AV10,">0")+COUNTIF(AY10,">0")+COUNTIF(BB10,">0")+COUNTIF(BE10,">0")+COUNTIF(BH10,">0")+COUNTIF(BK10,">0") -> 0 | AB10: =SUM(AC10,AF10,AI10,AL10,AO10,AR10,AU10,AX10,BA10,BD10,BG10,BJ10) -> 0 | AC10: =AD10*AE10 -> 0 | AD10: ='1-2 人员岗位信息'!F15 -> 0 | AF10: =AG10*AH10 -> 0 | AG10: =SUMIFS('1-2 人员岗位信息'!G:G,'1-2 人员岗位信息'!$C:$C,"自有人员",'1-2 人员岗位信息'!$B:$B,$D10) -> 0 | AI10: =AJ10*AK10 -> 0 | AJ10: =SUMIFS('1-2 人员岗位信息'!H:H,'1-2 人员岗位信息'!$C:$C,"自有人员",'1-2 人员岗位信息'!$B:$B,$D10) -> 0 | AL10: =AM10*AN10 -> 0 | AM10: =SUMIFS('1-2 人员岗位信息'!I:I,'1-2 人员岗位信息'!$C:$C,"自有人员",'1-2 人员岗位信息'!$B:$B,$D10) -> 0 | AO10: =AP10*AQ10 -> 0 | AP10: =SUMIFS('1-2 人员岗位信息'!J:J,'1-2 人员岗位信息'!$C:$C,"自有人员",'1-2 人员岗位信息'!$B:$B,$D10) -> 0 | AR10: =AS10*AT10 -> 0 | AS10: =SUMIFS('1-2 人员岗位信息'!K:K,'1-2 人员岗位信息'!$C:$C,"自有人员",'1-2 人员岗位信息'!$B:$B,$D10) -> 0 | AU10: =AV10*AW10 -> 0 | AV10: =SUMIFS('1-2 人员岗位信息'!L:L,'1-2 人员岗位信息'!$C:$C,"自有人员",'1-2 人员岗位信息'!$B:$B,$D10) -> 0 | AX10: =AY10*AZ10 -> 0 | AY10: =SUMIFS('1-2 人员岗位信息'!M:M,'1-2 人员岗位信息'!$C:$C,"自有人员",'1-2 人员岗位信息'!$B:$B,$D10) -> 0 | BA10: =BB10*BC10 -> 0 | BB10: =SUMIFS('1-2 人员岗位信息'!N:N,'1-2 人员岗位信息'!$C:$C,"自有人员",'1-2 人员岗位信息'!$B:$B,$D10) -> 0 | BD10: =BE10*BF10 -> 0 | BE10: =SUMIFS('1-2 人员岗位信息'!O:O,'1-2 人员岗位信息'!$C:$C,"自有人员",'1-2 人员岗位信息'!$B:$B,$D10) -> 0 | BG10: =BH10*BI10 -> 0 | BH10: =SUMIFS('1-2 人员岗位信息'!P:P,'1-2 人员岗位信息'!$C:$C,"自有人员",'1-2 人员岗位信息'!$B:$B,$D10) -> 0 | BJ10: =BK10*BL10 -> 0 | BK10: =SUMIFS('1-2 人员岗位信息'!Q:Q,'1-2 人员岗位信息'!$C:$C,"自有人员",'1-2 人员岗位信息'!$B:$B,$D10) -> 0
B11: 是 | C11: 1.1.1.1.1.3 | D11: 门岗员工 | E11: 含车岗、形象岗、商写礼宾岗 | G11: 按月编制，汇总成年总量 | H11: =AB11 -> 0 | I11: 岗位数量 | J11: =SUM(AD11,AG11,AJ11,AM11,AP11,AS11,AV11,AY11,BB11,BE11,BH11,BK11)/N11 -> #DIV/0! | K11: 岗 | L11: =H11/N11/J11 -> #DIV/0! | M11: 元/㎡/月 | N11: =COUNTIF(AD11,">0")+COUNTIF(AG11,">0")+COUNTIF(AJ11,">0")+COUNTIF(AM11,">0")+COUNTIF(AP11,">0")+COUNTIF(AS11,">0")+COUNTIF(AV11,">0")+COUNTIF(AY11,">0")+COUNTIF(BB11,">0")+COUNTIF(BE11,">0")+COUNTIF(BH11,">0")+COUNTIF(BK11,">0") -> 0 | AB11: =SUM(AC11,AF11,AI11,AL11,AO11,AR11,AU11,AX11,BA11,BD11,BG11,BJ11) -> 0 | AC11: =AD11*AE11 -> 0 | AD11: ='1-2 人员岗位信息'!F19 -> 0 | AF11: =AG11*AH11 -> 0 | AG11: =SUMIFS('1-2 人员岗位信息'!G:G,'1-2 人员岗位信息'!$C:$C,"自有人员",'1-2 人员岗位信息'!$B:$B,$D11) -> 0 | AI11: =AJ11*AK11 -> 0 | AJ11: =SUMIFS('1-2 人员岗位信息'!H:H,'1-2 人员岗位信息'!$C:$C,"自有人员",'1-2 人员岗位信息'!$B:$B,$D11) -> 0 | AL11: =AM11*AN11 -> 0 | AM11: =SUMIFS('1-2 人员岗位信息'!I:I,'1-2 人员岗位信息'!$C:$C,"自有人员",'1-2 人员岗位信息'!$B:$B,$D11) -> 0 | AO11: =AP11*AQ11 -> 0 | AP11: =SUMIFS('1-2 人员岗位信息'!J:J,'1-2 人员岗位信息'!$C:$C,"自有人员",'1-2 人员岗位信息'!$B:$B,$D11) -> 0 | AR11: =AS11*AT11 -> 0 | AS11: =SUMIFS('1-2 人员岗位信息'!K:K,'1-2 人员岗位信息'!$C:$C,"自有人员",'1-2 人员岗位信息'!$B:$B,$D11) -> 0 | AU11: =AV11*AW11 -> 0 | AV11: =SUMIFS('1-2 人员岗位信息'!L:L,'1-2 人员岗位信息'!$C:$C,"自有人员",'1-2 人员岗位信息'!$B:$B,$D11) -> 0 | AX11: =AY11*AZ11 -> 0 | AY11: =SUMIFS('1-2 人员岗位信息'!M:M,'1-2 人员岗位信息'!$C:$C,"自有人员",'1-2 人员岗位信息'!$B:$B,$D11) -> 0 | BA11: =BB11*BC11 -> 0 | BB11: =SUMIFS('1-2 人员岗位信息'!N:N,'1-2 人员岗位信息'!$C:$C,"自有人员",'1-2 人员岗位信息'!$B:$B,$D11) -> 0 | BD11: =BE11*BF11 -> 0 | BE11: =SUMIFS('1-2 人员岗位信息'!O:O,'1-2 人员岗位信息'!$C:$C,"自有人员",'1-2 人员岗位信息'!$B:$B,$D11) -> 0 | BG11: =BH11*BI11 -> 0 | BH11: =SUMIFS('1-2 人员岗位信息'!P:P,'1-2 人员岗位信息'!$C:$C,"自有人员",'1-2 人员岗位信息'!$B:$B,$D11) -> 0 | BJ11: =BK11*BL11 -> 0 | BK11: =SUMIFS('1-2 人员岗位信息'!Q:Q,'1-2 人员岗位信息'!$C:$C,"自有人员",'1-2 人员岗位信息'!$B:$B,$D11) -> 0
B12: 是 | C12: 1.1.1.1.1.4 | D12: 巡逻岗员工 | E12: 含机动岗 | G12: 按月编制，汇总成年总量 | H12: =AB12 -> 0 | I12: 岗位数量 | J12: =SUM(AD12,AG12,AJ12,AM12,AP12,AS12,AV12,AY12,BB12,BE12,BH12,BK12)/N12 -> #DIV/0! | K12: 岗 | L12: =H12/N12/J12 -> #DIV/0! | M12: 元/㎡/月 | N12: =COUNTIF(AD12,">0")+COUNTIF(AG12,">0")+COUNTIF(AJ12,">0")+COUNTIF(AM12,">0")+COUNTIF(AP12,">0")+COUNTIF(AS12,">0")+COUNTIF(AV12,">0")+COUNTIF(AY12,">0")+COUNTIF(BB12,">0")+COUNTIF(BE12,">0")+COUNTIF(BH12,">0")+COUNTIF(BK12,">0") -> 0 | AB12: =SUM(AC12,AF12,AI12,AL12,AO12,AR12,AU12,AX12,BA12,BD12,BG12,BJ12) -> 0 | AC12: =AD12*AE12 -> 0 | AD12: ='1-2 人员岗位信息'!F23 -> 0 | AF12: =AG12*AH12 -> 0 | AG12: =SUMIFS('1-2 人员岗位信息'!G:G,'1-2 人员岗位信息'!$C:$C,"自有人员",'1-2 人员岗位信息'!$B:$B,$D12) -> 0 | AI12: =AJ12*AK12 -> 0 | AJ12: =SUMIFS('1-2 人员岗位信息'!H:H,'1-2 人员岗位信息'!$C:$C,"自有人员",'1-2 人员岗位信息'!$B:$B,$D12) -> 0 | AL12: =AM12*AN12 -> 0 | AM12: =SUMIFS('1-2 人员岗位信息'!I:I,'1-2 人员岗位信息'!$C:$C,"自有人员",'1-2 人员岗位信息'!$B:$B,$D12) -> 0 | AO12: =AP12*AQ12 -> 0 | AP12: =SUMIFS('1-2 人员岗位信息'!J:J,'1-2 人员岗位信息'!$C:$C,"自有人员",'1-2 人员岗位信息'!$B:$B,$D12) -> 0 | AR12: =AS12*AT12 -> 0 | AS12: =SUMIFS('1-2 人员岗位信息'!K:K,'1-2 人员岗位信息'!$C:$C,"自有人员",'1-2 人员岗位信息'!$B:$B,$D12) -> 0 | AU12: =AV12*AW12 -> 0 | AV12: =SUMIFS('1-2 人员岗位信息'!L:L,'1-2 人员岗位信息'!$C:$C,"自有人员",'1-2 人员岗位信息'!$B:$B,$D12) -> 0 | AX12: =AY12*AZ12 -> 0 | AY12: =SUMIFS('1-2 人员岗位信息'!M:M,'1-2 人员岗位信息'!$C:$C,"自有人员",'1-2 人员岗位信息'!$B:$B,$D12) -> 0 | BA12: =BB12*BC12 -> 0 | BB12: =SUMIFS('1-2 人员岗位信息'!N:N,'1-2 人员岗位信息'!$C:$C,"自有人员",'1-2 人员岗位信息'!$B:$B,$D12) -> 0 | BD12: =BE12*BF12 -> 0 | BE12: =SUMIFS('1-2 人员岗位信息'!O:O,'1-2 人员岗位信息'!$C:$C,"自有人员",'1-2 人员岗位信息'!$B:$B,$D12) -> 0 | BG12: =BH12*BI12 -> 0 | BH12: =SUMIFS('1-2 人员岗位信息'!P:P,'1-2 人员岗位信息'!$C:$C,"自有人员",'1-2 人员岗位信息'!$B:$B,$D12) -> 0 | BJ12: =BK12*BL12 -> 0 | BK12: =SUMIFS('1-2 人员岗位信息'!Q:Q,'1-2 人员岗位信息'!$C:$C,"自有人员",'1-2 人员岗位信息'!$B:$B,$D12) -> 0
B13: 是 | C13: 1.1.1.1.1.5 | D13: 中控岗员工 | E13: 指中控室、监控室人员 | G13: 按月编制，汇总成年总量 | H13: =AB13 -> 0 | I13: 岗位数量 | J13: =SUM(AD13,AG13,AJ13,AM13,AP13,AS13,AV13,AY13,BB13,BE13,BH13,BK13)/N13 -> #DIV/0! | K13: 岗 | L13: =H13/N13/J13 -> #DIV/0! | M13: 元/㎡/月 | N13: =COUNTIF(AD13,">0")+COUNTIF(AG13,">0")+COUNTIF(AJ13,">0")+COUNTIF(AM13,">0")+COUNTIF(AP13,">0")+COUNTIF(AS13,">0")+COUNTIF(AV13,">0")+COUNTIF(AY13,">0")+COUNTIF(BB13,">0")+COUNTIF(BE13,">0")+COUNTIF(BH13,">0")+COUNTIF(BK13,">0") -> 0 | AB13: =SUM(AC13,AF13,AI13,AL13,AO13,AR13,AU13,AX13,BA13,BD13,BG13,BJ13) -> 0 | AC13: =AD13*AE13 -> 0 | AD13: ='1-2 人员岗位信息'!F27 -> 0 | AF13: =AG13*AH13 -> 0 | AG13: =SUMIFS('1-2 人员岗位信息'!G:G,'1-2 人员岗位信息'!$C:$C,"自有人员",'1-2 人员岗位信息'!$B:$B,$D13) -> 0 | AI13: =AJ13*AK13 -> 0 | AJ13: =SUMIFS('1-2 人员岗位信息'!H:H,'1-2 人员岗位信息'!$C:$C,"自有人员",'1-2 人员岗位信息'!$B:$B,$D13) -> 0 | AL13: =AM13*AN13 -> 0 | AM13: =SUMIFS('1-2 人员岗位信息'!I:I,'1-2 人员岗位信息'!$C:$C,"自有人员",'1-2 人员岗位信息'!$B:$B,$D13) -> 0 | AO13: =AP13*AQ13 -> 0 | AP13: =SUMIFS('1-2 人员岗位信息'!J:J,'1-2 人员岗位信息'!$C:$C,"自有人员",'1-2 人员岗位信息'!$B:$B,$D13) -> 0 | AR13: =AS13*AT13 -> 0 | AS13: =SUMIFS('1-2 人员岗位信息'!K:K,'1-2 人员岗位信息'!$C:$C,"自有人员",'1-2 人员岗位信息'!$B:$B,$D13) -> 0 | AU13: =AV13*AW13 -> 0 | AV13: =SUMIFS('1-2 人员岗位信息'!L:L,'1-2 人员岗位信息'!$C:$C,"自有人员",'1-2 人员岗位信息'!$B:$B,$D13) -> 0 | AX13: =AY13*AZ13 -> 0 | AY13: =SUMIFS('1-2 人员岗位信息'!M:M,'1-2 人员岗位信息'!$C:$C,"自有人员",'1-2 人员岗位信息'!$B:$B,$D13) -> 0 | BA13: =BB13*BC13 -> 0 | BB13: =SUMIFS('1-2 人员岗位信息'!N:N,'1-2 人员岗位信息'!$C:$C,"自有人员",'1-2 人员岗位信息'!$B:$B,$D13) -> 0 | BD13: =BE13*BF13 -> 0 | BE13: =SUMIFS('1-2 人员岗位信息'!O:O,'1-2 人员岗位信息'!$C:$C,"自有人员",'1-2 人员岗位信息'!$B:$B,$D13) -> 0 | BG13: =BH13*BI13 -> 0 | BH13: =SUMIFS('1-2 人员岗位信息'!P:P,'1-2 人员岗位信息'!$C:$C,"自有人员",'1-2 人员岗位信息'!$B:$B,$D13) -> 0 | BJ13: =BK13*BL13 -> 0 | BK13: =SUMIFS('1-2 人员岗位信息'!Q:Q,'1-2 人员岗位信息'!$C:$C,"自有人员",'1-2 人员岗位信息'!$B:$B,$D13) -> 0
B14: 是 | C14: 1.1.1.1.1.6 | D14: 其他保安员工 | E14: 上述不包含的岗位可适用此项 | G14: 按月编制，汇总成年总量 | H14: =AB14 -> 0 | I14: 岗位数量 | J14: =SUM(AD14,AG14,AJ14,AM14,AP14,AS14,AV14,AY14,BB14,BE14,BH14,BK14)/N14 -> #DIV/0! | K14: 岗 | L14: =H14/N14/J14 -> #DIV/0! | M14: 元/㎡/月 | N14: =COUNTIF(AD14,">0")+COUNTIF(AG14,">0")+COUNTIF(AJ14,">0")+COUNTIF(AM14,">0")+COUNTIF(AP14,">0")+COUNTIF(AS14,">0")+COUNTIF(AV14,">0")+COUNTIF(AY14,">0")+COUNTIF(BB14,">0")+COUNTIF(BE14,">0")+COUNTIF(BH14,">0")+COUNTIF(BK14,">0") -> 0 | AB14: =SUM(AC14,AF14,AI14,AL14,AO14,AR14,AU14,AX14,BA14,BD14,BG14,BJ14) -> 0 | AC14: =AD14*AE14 -> 0 | AD14: ='1-2 人员岗位信息'!F31 -> 0 | AF14: =AG14*AH14 -> 0 | AG14: =SUMIFS('1-2 人员岗位信息'!G:G,'1-2 人员岗位信息'!$C:$C,"自有人员",'1-2 人员岗位信息'!$B:$B,$D14) -> 0 | AI14: =AJ14*AK14 -> 0 | AJ14: =SUMIFS('1-2 人员岗位信息'!H:H,'1-2 人员岗位信息'!$C:$C,"自有人员",'1-2 人员岗位信息'!$B:$B,$D14) -> 0 | AL14: =AM14*AN14 -> 0 | AM14: =SUMIFS('1-2 人员岗位信息'!I:I,'1-2 人员岗位信息'!$C:$C,"自有人员",'1-2 人员岗位信息'!$B:$B,$D14) -> 0 | AO14: =AP14*AQ14 -> 0 | AP14: =SUMIFS('1-2 人员岗位信息'!J:J,'1-2 人员岗位信息'!$C:$C,"自有人员",'1-2 人员岗位信息'!$B:$B,$D14) -> 0 | AR14: =AS14*AT14 -> 0 | AS14: =SUMIFS('1-2 人员岗位信息'!K:K,'1-2 人员岗位信息'!$C:$C,"自有人员",'1-2 人员岗位信息'!$B:$B,$D14) -> 0 | AU14: =AV14*AW14 -> 0 | AV14: =SUMIFS('1-2 人员岗位信息'!L:L,'1-2 人员岗位信息'!$C:$C,"自有人员",'1-2 人员岗位信息'!$B:$B,$D14) -> 0 | AX14: =AY14*AZ14 -> 0 | AY14: =SUMIFS('1-2 人员岗位信息'!M:M,'1-2 人员岗位信息'!$C:$C,"自有人员",'1-2 人员岗位信息'!$B:$B,$D14) -> 0 | BA14: =BB14*BC14 -> 0 | BB14: =SUMIFS('1-2 人员岗位信息'!N:N,'1-2 人员岗位信息'!$C:$C,"自有人员",'1-2 人员岗位信息'!$B:$B,$D14) -> 0 | BD14: =BE14*BF14 -> 0 | BE14: =SUMIFS('1-2 人员岗位信息'!O:O,'1-2 人员岗位信息'!$C:$C,"自有人员",'1-2 人员岗位信息'!$B:$B,$D14) -> 0 | BG14: =BH14*BI14 -> 0 | BH14: =SUMIFS('1-2 人员岗位信息'!P:P,'1-2 人员岗位信息'!$C:$C,"自有人员",'1-2 人员岗位信息'!$B:$B,$D14) -> 0 | BJ14: =BK14*BL14 -> 0 | BK14: =SUMIFS('1-2 人员岗位信息'!Q:Q,'1-2 人员岗位信息'!$C:$C,"自有人员",'1-2 人员岗位信息'!$B:$B,$D14) -> 0
B15: 否 | C15: 1.1.1.1.2 | D15: 劳务派遣 | H15: =SUM(H16:H21) -> 0 | AB15: =SUM(AB16:AB21) -> 0 | AC15: =SUM(AC16:AC21) -> 0 | AF15: =SUM(AF16:AF21) -> 0 | AI15: =SUM(AI16:AI21) -> 0 | AL15: =SUM(AL16:AL21) -> 0 | AO15: =SUM(AO16:AO21) -> 0 | AR15: =SUM(AR16:AR21) -> 0 | AU15: =SUM(AU16:AU21) -> 0 | AX15: =SUM(AX16:AX21) -> 0 | BA15: =SUM(BA16:BA21) -> 0 | BD15: =SUM(BD16:BD21) -> 0 | BG15: =SUM(BG16:BG21) -> 0 | BJ15: =SUM(BJ16:BJ21) -> 0
B16: 是 | C16: 1.1.1.1.2.1 | D16: 保安经理 | E16: 指派遣保安经理 | G16: 按月编制，汇总成年总量 | H16: =AB16 -> 0 | I16: 岗位数量 | J16: =SUM(AD16,AG16,AJ16,AM16,AP16,AS16,AV16,AY16,BB16,BE16,BH16,BK16)/N16 -> #DIV/0! | K16: 岗 | L16: =H16/N16/J16 -> #DIV/0! | M16: 元/㎡/月 | N16: =COUNTIF(AD16,">0")+COUNTIF(AG16,">0")+COUNTIF(AJ16,">0")+COUNTIF(AM16,">0")+COUNTIF(AP16,">0")+COUNTIF(AS16,">0")+COUNTIF(AV16,">0")+COUNTIF(AY16,">0")+COUNTIF(BB16,">0")+COUNTIF(BE16,">0")+COUNTIF(BH16,">0")+COUNTIF(BK16,">0") -> 0 | AB16: =SUM(AC16,AF16,AI16,AL16,AO16,AR16,AU16,AX16,BA16,BD16,BG16,BJ16) -> 0 | AC16: =AD16*AE16 -> 0 | AD16: ='1-2 人员岗位信息'!F12 -> 0 | AF16: =AG16*AH16 -> 0 | AG16: =SUMIFS('1-2 人员岗位信息'!G:G,'1-2 人员岗位信息'!$C:$C,"劳务派遣",'1-2 人员岗位信息'!$B:$B,$D16) -> 0 | AI16: =AJ16*AK16 -> 0 | AJ16: =SUMIFS('1-2 人员岗位信息'!H:H,'1-2 人员岗位信息'!$C:$C,"劳务派遣",'1-2 人员岗位信息'!$B:$B,$D16) -> 0 | AL16: =AM16*AN16 -> 0 | AM16: =SUMIFS('1-2 人员岗位信息'!I:I,'1-2 人员岗位信息'!$C:$C,"劳务派遣",'1-2 人员岗位信息'!$B:$B,$D16) -> 0 | AO16: =AP16*AQ16 -> 0 | AP16: =SUMIFS('1-2 人员岗位信息'!J:J,'1-2 人员岗位信息'!$C:$C,"劳务派遣",'1-2 人员岗位信息'!$B:$B,$D16) -> 0 | AR16: =AS16*AT16 -> 0 | AS16: =SUMIFS('1-2 人员岗位信息'!K:K,'1-2 人员岗位信息'!$C:$C,"劳务派遣",'1-2 人员岗位信息'!$B:$B,$D16) -> 0 | AU16: =AV16*AW16 -> 0 | AV16: =SUMIFS('1-2 人员岗位信息'!L:L,'1-2 人员岗位信息'!$C:$C,"劳务派遣",'1-2 人员岗位信息'!$B:$B,$D16) -> 0 | AX16: =AY16*AZ16 -> 0 | AY16: =SUMIFS('1-2 人员岗位信息'!M:M,'1-2 人员岗位信息'!$C:$C,"劳务派遣",'1-2 人员岗位信息'!$B:$B,$D16) -> 0 | BA16: =BB16*BC16 -> 0 | BB16: =SUMIFS('1-2 人员岗位信息'!N:N,'1-2 人员岗位信息'!$C:$C,"劳务派遣",'1-2 人员岗位信息'!$B:$B,$D16) -> 0 | BD16: =BE16*BF16 -> 0 | BE16: =SUMIFS('1-2 人员岗位信息'!O:O,'1-2 人员岗位信息'!$C:$C,"劳务派遣",'1-2 人员岗位信息'!$B:$B,$D16) -> 0 | BG16: =BH16*BI16 -> 0 | BH16: =SUMIFS('1-2 人员岗位信息'!P:P,'1-2 人员岗位信息'!$C:$C,"劳务派遣",'1-2 人员岗位信息'!$B:$B,$D16) -> 0 | BJ16: =BK16*BL16 -> 0 | BK16: =SUMIFS('1-2 人员岗位信息'!Q:Q,'1-2 人员岗位信息'!$C:$C,"劳务派遣",'1-2 人员岗位信息'!$B:$B,$D16) -> 0
B17: 是 | C17: 1.1.1.1.2.2 | D17: 保安主管 | E17: 指派遣保安主管 | G17: 按月编制，汇总成年总量 | H17: =AB17 -> 0 | I17: 岗位数量 | J17: =SUM(AD17,AG17,AJ17,AM17,AP17,AS17,AV17,AY17,BB17,BE17,BH17,BK17)/N17 -> #DIV/0! | K17: 岗 | L17: =H17/N17/J17 -> #DIV/0! | M17: 元/㎡/月 | N17: =COUNTIF(AD17,">0")+COUNTIF(AG17,">0")+COUNTIF(AJ17,">0")+COUNTIF(AM17,">0")+COUNTIF(AP17,">0")+COUNTIF(AS17,">0")+COUNTIF(AV17,">0")+COUNTIF(AY17,">0")+COUNTIF(BB17,">0")+COUNTIF(BE17,">0")+COUNTIF(BH17,">0")+COUNTIF(BK17,">0") -> 0 | AB17: =SUM(AC17,AF17,AI17,AL17,AO17,AR17,AU17,AX17,BA17,BD17,BG17,BJ17) -> 0 | AC17: =AD17*AE17 -> 0 | AD17: ='1-2 人员岗位信息'!F16 -> 0 | AF17: =AG17*AH17 -> 0 | AG17: =SUMIFS('1-2 人员岗位信息'!G:G,'1-2 人员岗位信息'!$C:$C,"劳务派遣",'1-2 人员岗位信息'!$B:$B,$D17) -> 0 | AI17: =AJ17*AK17 -> 0 | AJ17: =SUMIFS('1-2 人员岗位信息'!H:H,'1-2 人员岗位信息'!$C:$C,"劳务派遣",'1-2 人员岗位信息'!$B:$B,$D17) -> 0 | AL17: =AM17*AN17 -> 0 | AM17: =SUMIFS('1-2 人员岗位信息'!I:I,'1-2 人员岗位信息'!$C:$C,"劳务派遣",'1-2 人员岗位信息'!$B:$B,$D17) -> 0 | AO17: =AP17*AQ17 -> 0 | AP17: =SUMIFS('1-2 人员岗位信息'!J:J,'1-2 人员岗位信息'!$C:$C,"劳务派遣",'1-2 人员岗位信息'!$B:$B,$D17) -> 0 | AR17: =AS17*AT17 -> 0 | AS17: =SUMIFS('1-2 人员岗位信息'!K:K,'1-2 人员岗位信息'!$C:$C,"劳务派遣",'1-2 人员岗位信息'!$B:$B,$D17) -> 0 | AU17: =AV17*AW17 -> 0 | AV17: =SUMIFS('1-2 人员岗位信息'!L:L,'1-2 人员岗位信息'!$C:$C,"劳务派遣",'1-2 人员岗位信息'!$B:$B,$D17) -> 0 | AX17: =AY17*AZ17 -> 0 | AY17: =SUMIFS('1-2 人员岗位信息'!M:M,'1-2 人员岗位信息'!$C:$C,"劳务派遣",'1-2 人员岗位信息'!$B:$B,$D17) -> 0 | BA17: =BB17*BC17 -> 0 | BB17: =SUMIFS('1-2 人员岗位信息'!N:N,'1-2 人员岗位信息'!$C:$C,"劳务派遣",'1-2 人员岗位信息'!$B:$B,$D17) -> 0 | BD17: =BE17*BF17 -> 0 | BE17: =SUMIFS('1-2 人员岗位信息'!O:O,'1-2 人员岗位信息'!$C:$C,"劳务派遣",'1-2 人员岗位信息'!$B:$B,$D17) -> 0 | BG17: =BH17*BI17 -> 0 | BH17: =SUMIFS('1-2 人员岗位信息'!P:P,'1-2 人员岗位信息'!$C:$C,"劳务派遣",'1-2 人员岗位信息'!$B:$B,$D17) -> 0 | BJ17: =BK17*BL17 -> 0 | BK17: =SUMIFS('1-2 人员岗位信息'!Q:Q,'1-2 人员岗位信息'!$C:$C,"劳务派遣",'1-2 人员岗位信息'!$B:$B,$D17) -> 0
B18: 是 | C18: 1.1.1.1.2.3 | D18: 门岗员工 | E18: 含车岗、形象岗、商写礼宾岗 | G18: 按月编制，汇总成年总量 | H18: =AB18 -> 0 | I18: 岗位数量 | J18: =SUM(AD18,AG18,AJ18,AM18,AP18,AS18,AV18,AY18,BB18,BE18,BH18,BK18)/N18 -> #DIV/0! | K18: 岗 | L18: =H18/N18/J18 -> #DIV/0! | M18: 元/㎡/月 | N18: =COUNTIF(AD18,">0")+COUNTIF(AG18,">0")+COUNTIF(AJ18,">0")+COUNTIF(AM18,">0")+COUNTIF(AP18,">0")+COUNTIF(AS18,">0")+COUNTIF(AV18,">0")+COUNTIF(AY18,">0")+COUNTIF(BB18,">0")+COUNTIF(BE18,">0")+COUNTIF(BH18,">0")+COUNTIF(BK18,">0") -> 0 | AB18: =SUM(AC18,AF18,AI18,AL18,AO18,AR18,AU18,AX18,BA18,BD18,BG18,BJ18) -> 0 | AC18: =AD18*AE18 -> 0 | AD18: ='1-2 人员岗位信息'!F20 -> 0 | AF18: =AG18*AH18 -> 0 | AG18: =SUMIFS('1-2 人员岗位信息'!G:G,'1-2 人员岗位信息'!$C:$C,"劳务派遣",'1-2 人员岗位信息'!$B:$B,$D18) -> 0 | AI18: =AJ18*AK18 -> 0 | AJ18: =SUMIFS('1-2 人员岗位信息'!H:H,'1-2 人员岗位信息'!$C:$C,"劳务派遣",'1-2 人员岗位信息'!$B:$B,$D18) -> 0 | AL18: =AM18*AN18 -> 0 | AM18: =SUMIFS('1-2 人员岗位信息'!I:I,'1-2 人员岗位信息'!$C:$C,"劳务派遣",'1-2 人员岗位信息'!$B:$B,$D18) -> 0 | AO18: =AP18*AQ18 -> 0 | AP18: =SUMIFS('1-2 人员岗位信息'!J:J,'1-2 人员岗位信息'!$C:$C,"劳务派遣",'1-2 人员岗位信息'!$B:$B,$D18) -> 0 | AR18: =AS18*AT18 -> 0 | AS18: =SUMIFS('1-2 人员岗位信息'!K:K,'1-2 人员岗位信息'!$C:$C,"劳务派遣",'1-2 人员岗位信息'!$B:$B,$D18) -> 0 | AU18: =AV18*AW18 -> 0 | AV18: =SUMIFS('1-2 人员岗位信息'!L:L,'1-2 人员岗位信息'!$C:$C,"劳务派遣",'1-2 人员岗位信息'!$B:$B,$D18) -> 0 | AX18: =AY18*AZ18 -> 0 | AY18: =SUMIFS('1-2 人员岗位信息'!M:M,'1-2 人员岗位信息'!$C:$C,"劳务派遣",'1-2 人员岗位信息'!$B:$B,$D18) -> 0 | BA18: =BB18*BC18 -> 0 | BB18: =SUMIFS('1-2 人员岗位信息'!N:N,'1-2 人员岗位信息'!$C:$C,"劳务派遣",'1-2 人员岗位信息'!$B:$B,$D18) -> 0 | BD18: =BE18*BF18 -> 0 | BE18: =SUMIFS('1-2 人员岗位信息'!O:O,'1-2 人员岗位信息'!$C:$C,"劳务派遣",'1-2 人员岗位信息'!$B:$B,$D18) -> 0 | BG18: =BH18*BI18 -> 0 | BH18: =SUMIFS('1-2 人员岗位信息'!P:P,'1-2 人员岗位信息'!$C:$C,"劳务派遣",'1-2 人员岗位信息'!$B:$B,$D18) -> 0 | BJ18: =BK18*BL18 -> 0 | BK18: =SUMIFS('1-2 人员岗位信息'!Q:Q,'1-2 人员岗位信息'!$C:$C,"劳务派遣",'1-2 人员岗位信息'!$B:$B,$D18) -> 0
B19: 是 | C19: 1.1.1.1.2.4 | D19: 巡逻岗员工 | E19: 含机动岗 | G19: 按月编制，汇总成年总量 | H19: =AB19 -> 0 | I19: 岗位数量 | J19: =SUM(AD19,AG19,AJ19,AM19,AP19,AS19,AV19,AY19,BB19,BE19,BH19,BK19)/N19 -> #DIV/0! | K19: 岗 | L19: =H19/N19/J19 -> #DIV/0! | M19: 元/㎡/月 | N19: =COUNTIF(AD19,">0")+COUNTIF(AG19,">0")+COUNTIF(AJ19,">0")+COUNTIF(AM19,">0")+COUNTIF(AP19,">0")+COUNTIF(AS19,">0")+COUNTIF(AV19,">0")+COUNTIF(AY19,">0")+COUNTIF(BB19,">0")+COUNTIF(BE19,">0")+COUNTIF(BH19,">0")+COUNTIF(BK19,">0") -> 0 | AB19: =SUM(AC19,AF19,AI19,AL19,AO19,AR19,AU19,AX19,BA19,BD19,BG19,BJ19) -> 0 | AC19: =AD19*AE19 -> 0 | AD19: ='1-2 人员岗位信息'!F24 -> 0 | AF19: =AG19*AH19 -> 0 | AG19: =SUMIFS('1-2 人员岗位信息'!G:G,'1-2 人员岗位信息'!$C:$C,"劳务派遣",'1-2 人员岗位信息'!$B:$B,$D19) -> 0 | AI19: =AJ19*AK19 -> 0 | AJ19: =SUMIFS('1-2 人员岗位信息'!H:H,'1-2 人员岗位信息'!$C:$C,"劳务派遣",'1-2 人员岗位信息'!$B:$B,$D19) -> 0 | AL19: =AM19*AN19 -> 0 | AM19: =SUMIFS('1-2 人员岗位信息'!I:I,'1-2 人员岗位信息'!$C:$C,"劳务派遣",'1-2 人员岗位信息'!$B:$B,$D19) -> 0 | AO19: =AP19*AQ19 -> 0 | AP19: =SUMIFS('1-2 人员岗位信息'!J:J,'1-2 人员岗位信息'!$C:$C,"劳务派遣",'1-2 人员岗位信息'!$B:$B,$D19) -> 0 | AR19: =AS19*AT19 -> 0 | AS19: =SUMIFS('1-2 人员岗位信息'!K:K,'1-2 人员岗位信息'!$C:$C,"劳务派遣",'1-2 人员岗位信息'!$B:$B,$D19) -> 0 | AU19: =AV19*AW19 -> 0 | AV19: =SUMIFS('1-2 人员岗位信息'!L:L,'1-2 人员岗位信息'!$C:$C,"劳务派遣",'1-2 人员岗位信息'!$B:$B,$D19) -> 0 | AX19: =AY19*AZ19 -> 0 | AY19: =SUMIFS('1-2 人员岗位信息'!M:M,'1-2 人员岗位信息'!$C:$C,"劳务派遣",'1-2 人员岗位信息'!$B:$B,$D19) -> 0 | BA19: =BB19*BC19 -> 0 | BB19: =SUMIFS('1-2 人员岗位信息'!N:N,'1-2 人员岗位信息'!$C:$C,"劳务派遣",'1-2 人员岗位信息'!$B:$B,$D19) -> 0 | BD19: =BE19*BF19 -> 0 | BE19: =SUMIFS('1-2 人员岗位信息'!O:O,'1-2 人员岗位信息'!$C:$C,"劳务派遣",'1-2 人员岗位信息'!$B:$B,$D19) -> 0 | BG19: =BH19*BI19 -> 0 | BH19: =SUMIFS('1-2 人员岗位信息'!P:P,'1-2 人员岗位信息'!$C:$C,"劳务派遣",'1-2 人员岗位信息'!$B:$B,$D19) -> 0 | BJ19: =BK19*BL19 -> 0 | BK19: =SUMIFS('1-2 人员岗位信息'!Q:Q,'1-2 人员岗位信息'!$C:$C,"劳务派遣",'1-2 人员岗位信息'!$B:$B,$D19) -> 0
B20: 是 | C20: 1.1.1.1.2.5 | D20: 中控岗员工 | E20: 指中控室、监控室人员 | G20: 按月编制，汇总成年总量 | H20: =AB20 -> 0 | I20: 岗位数量 | J20: =SUM(AD20,AG20,AJ20,AM20,AP20,AS20,AV20,AY20,BB20,BE20,BH20,BK20)/N20 -> #DIV/0! | K20: 岗 | L20: =H20/N20/J20 -> #DIV/0! | M20: 元/㎡/月 | N20: =COUNTIF(AD20,">0")+COUNTIF(AG20,">0")+COUNTIF(AJ20,">0")+COUNTIF(AM20,">0")+COUNTIF(AP20,">0")+COUNTIF(AS20,">0")+COUNTIF(AV20,">0")+COUNTIF(AY20,">0")+COUNTIF(BB20,">0")+COUNTIF(BE20,">0")+COUNTIF(BH20,">0")+COUNTIF(BK20,">0") -> 0 | AB20: =SUM(AC20,AF20,AI20,AL20,AO20,AR20,AU20,AX20,BA20,BD20,BG20,BJ20) -> 0 | AC20: =AD20*AE20 -> 0 | AD20: ='1-2 人员岗位信息'!F28 -> 0 | AF20: =AG20*AH20 -> 0 | AG20: =SUMIFS('1-2 人员岗位信息'!G:G,'1-2 人员岗位信息'!$C:$C,"劳务派遣",'1-2 人员岗位信息'!$B:$B,$D20) -> 0 | AI20: =AJ20*AK20 -> 0 | AJ20: =SUMIFS('1-2 人员岗位信息'!H:H,'1-2 人员岗位信息'!$C:$C,"劳务派遣",'1-2 人员岗位信息'!$B:$B,$D20) -> 0 | AL20: =AM20*AN20 -> 0 | AM20: =SUMIFS('1-2 人员岗位信息'!I:I,'1-2 人员岗位信息'!$C:$C,"劳务派遣",'1-2 人员岗位信息'!$B:$B,$D20) -> 0 | AO20: =AP20*AQ20 -> 0 | AP20: =SUMIFS('1-2 人员岗位信息'!J:J,'1-2 人员岗位信息'!$C:$C,"劳务派遣",'1-2 人员岗位信息'!$B:$B,$D20) -> 0 | AR20: =AS20*AT20 -> 0 | AS20: =SUMIFS('1-2 人员岗位信息'!K:K,'1-2 人员岗位信息'!$C:$C,"劳务派遣",'1-2 人员岗位信息'!$B:$B,$D20) -> 0 | AU20: =AV20*AW20 -> 0 | AV20: =SUMIFS('1-2 人员岗位信息'!L:L,'1-2 人员岗位信息'!$C:$C,"劳务派遣",'1-2 人员岗位信息'!$B:$B,$D20) -> 0 | AX20: =AY20*AZ20 -> 0 | AY20: =SUMIFS('1-2 人员岗位信息'!M:M,'1-2 人员岗位信息'!$C:$C,"劳务派遣",'1-2 人员岗位信息'!$B:$B,$D20) -> 0 | BA20: =BB20*BC20 -> 0 | BB20: =SUMIFS('1-2 人员岗位信息'!N:N,'1-2 人员岗位信息'!$C:$C,"劳务派遣",'1-2 人员岗位信息'!$B:$B,$D20) -> 0 | BD20: =BE20*BF20 -> 0 | BE20: =SUMIFS('1-2 人员岗位信息'!O:O,'1-2 人员岗位信息'!$C:$C,"劳务派遣",'1-2 人员岗位信息'!$B:$B,$D20) -> 0 | BG20: =BH20*BI20 -> 0 | BH20: =SUMIFS('1-2 人员岗位信息'!P:P,'1-2 人员岗位信息'!$C:$C,"劳务派遣",'1-2 人员岗位信息'!$B:$B,$D20) -> 0 | BJ20: =BK20*BL20 -> 0 | BK20: =SUMIFS('1-2 人员岗位信息'!Q:Q,'1-2 人员岗位信息'!$C:$C,"劳务派遣",'1-2 人员岗位信息'!$B:$B,$D20) -> 0
B21: 是 | C21: 1.1.1.1.2.6 | D21: 其他保安员工 | E21: 上述不包含的岗位可适用此项 | G21: 按月编制，汇总成年总量 | H21: =AB21 -> 0 | I21: 岗位数量 | J21: =SUM(AD21,AG21,AJ21,AM21,AP21,AS21,AV21,AY21,BB21,BE21,BH21,BK21)/N21 -> #DIV/0! | K21: 岗 | L21: =H21/N21/J21 -> #DIV/0! | M21: 元/㎡/月 | N21: =COUNTIF(AD21,">0")+COUNTIF(AG21,">0")+COUNTIF(AJ21,">0")+COUNTIF(AM21,">0")+COUNTIF(AP21,">0")+COUNTIF(AS21,">0")+COUNTIF(AV21,">0")+COUNTIF(AY21,">0")+COUNTIF(BB21,">0")+COUNTIF(BE21,">0")+COUNTIF(BH21,">0")+COUNTIF(BK21,">0") -> 0 | AB21: =SUM(AC21,AF21,AI21,AL21,AO21,AR21,AU21,AX21,BA21,BD21,BG21,BJ21) -> 0 | AC21: =AD21*AE21 -> 0 | AD21: ='1-2 人员岗位信息'!F32 -> 0 | AF21: =AG21*AH21 -> 0 | AG21: =SUMIFS('1-2 人员岗位信息'!G:G,'1-2 人员岗位信息'!$C:$C,"劳务派遣",'1-2 人员岗位信息'!$B:$B,$D21) -> 0 | AI21: =AJ21*AK21 -> 0 | AJ21: =SUMIFS('1-2 人员岗位信息'!H:H,'1-2 人员岗位信息'!$C:$C,"劳务派遣",'1-2 人员岗位信息'!$B:$B,$D21) -> 0 | AL21: =AM21*AN21 -> 0 | AM21: =SUMIFS('1-2 人员岗位信息'!I:I,'1-2 人员岗位信息'!$C:$C,"劳务派遣",'1-2 人员岗位信息'!$B:$B,$D21) -> 0 | AO21: =AP21*AQ21 -> 0 | AP21: =SUMIFS('1-2 人员岗位信息'!J:J,'1-2 人员岗位信息'!$C:$C,"劳务派遣",'1-2 人员岗位信息'!$B:$B,$D21) -> 0 | AR21: =AS21*AT21 -> 0 | AS21: =SUMIFS('1-2 人员岗位信息'!K:K,'1-2 人员岗位信息'!$C:$C,"劳务派遣",'1-2 人员岗位信息'!$B:$B,$D21) -> 0 | AU21: =AV21*AW21 -> 0 | AV21: =SUMIFS('1-2 人员岗位信息'!L:L,'1-2 人员岗位信息'!$C:$C,"劳务派遣",'1-2 人员岗位信息'!$B:$B,$D21) -> 0 | AX21: =AY21*AZ21 -> 0 | AY21: =SUMIFS('1-2 人员岗位信息'!M:M,'1-2 人员岗位信息'!$C:$C,"劳务派遣",'1-2 人员岗位信息'!$B:$B,$D21) -> 0 | BA21: =BB21*BC21 -> 0 | BB21: =SUMIFS('1-2 人员岗位信息'!N:N,'1-2 人员岗位信息'!$C:$C,"劳务派遣",'1-2 人员岗位信息'!$B:$B,$D21) -> 0 | BD21: =BE21*BF21 -> 0 | BE21: =SUMIFS('1-2 人员岗位信息'!O:O,'1-2 人员岗位信息'!$C:$C,"劳务派遣",'1-2 人员岗位信息'!$B:$B,$D21) -> 0 | BG21: =BH21*BI21 -> 0 | BH21: =SUMIFS('1-2 人员岗位信息'!P:P,'1-2 人员岗位信息'!$C:$C,"劳务派遣",'1-2 人员岗位信息'!$B:$B,$D21) -> 0 | BJ21: =BK20*BL21 -> 0 | BK21: =SUMIFS('1-2 人员岗位信息'!Q:Q,'1-2 人员岗位信息'!$C:$C,"劳务派遣",'1-2 人员岗位信息'!$B:$B,$D21) -> 0
B22: 否 | C22: 1.1.1.1.3 | D22: 专业外包 | H22: =SUM(H23:H28) -> 0 | AB22: =SUM(AB23:AB28) -> 0 | AC22: =SUM(AC23:AC28) -> 0 | AF22: =SUM(AF23:AF28) -> 0 | AI22: =SUM(AI23:AI28) -> 0 | AL22: =SUM(AL23:AL28) -> 0 | AO22: =SUM(AO23:AO28) -> 0 | AR22: =SUM(AR23:AR28) -> 0 | AU22: =SUM(AU23:AU28) -> 0 | AX22: =SUM(AX23:AX28) -> 0 | BA22: =SUM(BA23:BA28) -> 0 | BD22: =SUM(BD23:BD28) -> 0 | BG22: =SUM(BG23:BG28) -> 0 | BJ22: =SUM(BJ23:BJ28) -> 0
B23: 是 | C23: 1.1.1.1.3.1 | D23: 保安经理 | E23: 指外包保安经理 | G23: 按月编制，汇总成年总量 | H23: =AB23 -> 0 | I23: 岗位数量 | J23: =SUM(AD23,AG23,AJ23,AM23,AP23,AS23,AV23,AY23,BB23,BE23,BH23,BK23)/N23 -> #DIV/0! | K23: 岗 | L23: =H23/N23/J23 -> #DIV/0! | M23: 元/㎡/月 | N23: =COUNTIF(AD23,">0")+COUNTIF(AG23,">0")+COUNTIF(AJ23,">0")+COUNTIF(AM23,">0")+COUNTIF(AP23,">0")+COUNTIF(AS23,">0")+COUNTIF(AV23,">0")+COUNTIF(AY23,">0")+COUNTIF(BB23,">0")+COUNTIF(BE23,">0")+COUNTIF(BH23,">0")+COUNTIF(BK23,">0") -> 0 | AB23: =SUM(AC23,AF23,AI23,AL23,AO23,AR23,AU23,AX23,BA23,BD23,BG23,BJ23) -> 0 | AC23: =AD23*AE23 -> 0 | AD23: ='1-2 人员岗位信息'!F13 -> 0 | AE23: =IFERROR(预算主表!P80/(12*AD23),0) -> 0 | AF23: =AG23*AH23 -> 0 | AG23: =SUMIFS('1-2 人员岗位信息'!G:G,'1-2 人员岗位信息'!$C:$C,"专业外包",'1-2 人员岗位信息'!$B:$B,$D23) -> 0 | AH23: =AE23 -> 0 | AI23: =AJ23*AK23 -> 0 | AJ23: =SUMIFS('1-2 人员岗位信息'!H:H,'1-2 人员岗位信息'!$C:$C,"专业外包",'1-2 人员岗位信息'!$B:$B,$D23) -> 0 | AK23: =AE23 -> 0 | AL23: =AM23*AN23 -> 0 | AM23: =SUMIFS('1-2 人员岗位信息'!I:I,'1-2 人员岗位信息'!$C:$C,"专业外包",'1-2 人员岗位信息'!$B:$B,$D23) -> 0 | AN23: =AE23 -> 0 | AO23: =AP23*AQ23 -> 0 | AP23: =SUMIFS('1-2 人员岗位信息'!J:J,'1-2 人员岗位信息'!$C:$C,"专业外包",'1-2 人员岗位信息'!$B:$B,$D23) -> 0 | AQ23: =AE23 -> 0 | AR23: =AS23*AT23 -> 0 | AS23: =SUMIFS('1-2 人员岗位信息'!K:K,'1-2 人员岗位信息'!$C:$C,"专业外包",'1-2 人员岗位信息'!$B:$B,$D23) -> 0 | AT23: =AE23 -> 0 | AU23: =AV23*AW23 -> 0 | AV23: =SUMIFS('1-2 人员岗位信息'!L:L,'1-2 人员岗位信息'!$C:$C,"专业外包",'1-2 人员岗位信息'!$B:$B,$D23) -> 0 | AW23: =AE23 -> 0 | AX23: =AY23*AZ23 -> 0 | AY23: =SUMIFS('1-2 人员岗位信息'!M:M,'1-2 人员岗位信息'!$C:$C,"专业外包",'1-2 人员岗位信息'!$B:$B,$D23) -> 0 | AZ23: =AE23 -> 0 | BA23: =BB23*BC23 -> 0 | BB23: =SUMIFS('1-2 人员岗位信息'!N:N,'1-2 人员岗位信息'!$C:$C,"专业外包",'1-2 人员岗位信息'!$B:$B,$D23) -> 0 | BC23: =AE23 -> 0 | BD23: =BE23*BF23 -> 0 | BE23: =SUMIFS('1-2 人员岗位信息'!O:O,'1-2 人员岗位信息'!$C:$C,"专业外包",'1-2 人员岗位信息'!$B:$B,$D23) -> 0 | BF23: =AE23 -> 0 | BG23: =BH23*BI23 -> 0 | BH23: =SUMIFS('1-2 人员岗位信息'!P:P,'1-2 人员岗位信息'!$C:$C,"专业外包",'1-2 人员岗位信息'!$B:$B,$D23) -> 0 | BI23: =AE23 -> 0 | BJ23: =BK23*BL23 -> 0 | BK23: =SUMIFS('1-2 人员岗位信息'!Q:Q,'1-2 人员岗位信息'!$C:$C,"专业外包",'1-2 人员岗位信息'!$B:$B,$D23) -> 0 | BL23: =AE23 -> 0
B24: 是 | C24: 1.1.1.1.3.2 | D24: 保安主管 | E24: 指外包保安主管 | G24: 按月编制，汇总成年总量 | H24: =AB24 -> 0 | I24: 岗位数量 | J24: =SUM(AD24,AG24,AJ24,AM24,AP24,AS24,AV24,AY24,BB24,BE24,BH24,BK24)/N24 -> #DIV/0! | K24: 岗 | L24: =H24/N24/J24 -> #DIV/0! | M24: 元/㎡/月 | N24: =COUNTIF(AD24,">0")+COUNTIF(AG24,">0")+COUNTIF(AJ24,">0")+COUNTIF(AM24,">0")+COUNTIF(AP24,">0")+COUNTIF(AS24,">0")+COUNTIF(AV24,">0")+COUNTIF(AY24,">0")+COUNTIF(BB24,">0")+COUNTIF(BE24,">0")+COUNTIF(BH24,">0")+COUNTIF(BK24,">0") -> 0 | AB24: =SUM(AC24,AF24,AI24,AL24,AO24,AR24,AU24,AX24,BA24,BD24,BG24,BJ24) -> 0 | AC24: =AD24*AE24 -> 0 | AD24: ='1-2 人员岗位信息'!F17 -> 0 | AF24: =AG24*AH24 -> 0 | AG24: =SUMIFS('1-2 人员岗位信息'!G:G,'1-2 人员岗位信息'!$C:$C,"专业外包",'1-2 人员岗位信息'!$B:$B,$D24) -> 0 | AI24: =AJ24*AK24 -> 0 | AJ24: =SUMIFS('1-2 人员岗位信息'!H:H,'1-2 人员岗位信息'!$C:$C,"专业外包",'1-2 人员岗位信息'!$B:$B,$D24) -> 0 | AL24: =AM24*AN24 -> 0 | AM24: =SUMIFS('1-2 人员岗位信息'!I:I,'1-2 人员岗位信息'!$C:$C,"专业外包",'1-2 人员岗位信息'!$B:$B,$D24) -> 0 | AO24: =AP24*AQ24 -> 0 | AP24: =SUMIFS('1-2 人员岗位信息'!J:J,'1-2 人员岗位信息'!$C:$C,"专业外包",'1-2 人员岗位信息'!$B:$B,$D24) -> 0 | AR24: =AS24*AT24 -> 0 | AS24: =SUMIFS('1-2 人员岗位信息'!K:K,'1-2 人员岗位信息'!$C:$C,"专业外包",'1-2 人员岗位信息'!$B:$B,$D24) -> 0 | AU24: =AV24*AW24 -> 0 | AV24: =SUMIFS('1-2 人员岗位信息'!L:L,'1-2 人员岗位信息'!$C:$C,"专业外包",'1-2 人员岗位信息'!$B:$B,$D24) -> 0 | AX24: =AY24*AZ24 -> 0 | AY24: =SUMIFS('1-2 人员岗位信息'!M:M,'1-2 人员岗位信息'!$C:$C,"专业外包",'1-2 人员岗位信息'!$B:$B,$D24) -> 0 | BA24: =BB24*BC24 -> 0 | BB24: =SUMIFS('1-2 人员岗位信息'!N:N,'1-2 人员岗位信息'!$C:$C,"专业外包",'1-2 人员岗位信息'!$B:$B,$D24) -> 0 | BD24: =BE24*BF24 -> 0 | BE24: =SUMIFS('1-2 人员岗位信息'!O:O,'1-2 人员岗位信息'!$C:$C,"专业外包",'1-2 人员岗位信息'!$B:$B,$D24) -> 0 | BG24: =BH24*BI24 -> 0 | BH24: =SUMIFS('1-2 人员岗位信息'!P:P,'1-2 人员岗位信息'!$C:$C,"专业外包",'1-2 人员岗位信息'!$B:$B,$D24) -> 0 | BJ24: =BK24*BL24 -> 0 | BK24: =SUMIFS('1-2 人员岗位信息'!Q:Q,'1-2 人员岗位信息'!$C:$C,"专业外包",'1-2 人员岗位信息'!$B:$B,$D24) -> 0
B25: 是 | C25: 1.1.1.1.3.3 | D25: 门岗员工 | E25: 含车岗、形象岗、商写礼宾岗 | G25: 按月编制，汇总成年总量 | H25: =AB25 -> 0 | I25: 岗位数量 | J25: =SUM(AD25,AG25,AJ25,AM25,AP25,AS25,AV25,AY25,BB25,BE25,BH25,BK25)/N25 -> #DIV/0! | K25: 岗 | L25: =H25/N25/J25 -> #DIV/0! | M25: 元/㎡/月 | N25: =COUNTIF(AD25,">0")+COUNTIF(AG25,">0")+COUNTIF(AJ25,">0")+COUNTIF(AM25,">0")+COUNTIF(AP25,">0")+COUNTIF(AS25,">0")+COUNTIF(AV25,">0")+COUNTIF(AY25,">0")+COUNTIF(BB25,">0")+COUNTIF(BE25,">0")+COUNTIF(BH25,">0")+COUNTIF(BK25,">0") -> 0 | AB25: =SUM(AC25,AF25,AI25,AL25,AO25,AR25,AU25,AX25,BA25,BD25,BG25,BJ25) -> 0 | AC25: =AD25*AE25 -> 0 | AD25: ='1-2 人员岗位信息'!F21 -> 0 | AF25: =AG25*AH25 -> 0 | AG25: =SUMIFS('1-2 人员岗位信息'!G:G,'1-2 人员岗位信息'!$C:$C,"专业外包",'1-2 人员岗位信息'!$B:$B,$D25) -> 0 | AI25: =AJ25*AK25 -> 0 | AJ25: =SUMIFS('1-2 人员岗位信息'!H:H,'1-2 人员岗位信息'!$C:$C,"专业外包",'1-2 人员岗位信息'!$B:$B,$D25) -> 0 | AL25: =AM25*AN25 -> 0 | AM25: =SUMIFS('1-2 人员岗位信息'!I:I,'1-2 人员岗位信息'!$C:$C,"专业外包",'1-2 人员岗位信息'!$B:$B,$D25) -> 0 | AO25: =AP25*AQ25 -> 0 | AP25: =SUMIFS('1-2 人员岗位信息'!J:J,'1-2 人员岗位信息'!$C:$C,"专业外包",'1-2 人员岗位信息'!$B:$B,$D25) -> 0 | AR25: =AS25*AT25 -> 0 | AS25: =SUMIFS('1-2 人员岗位信息'!K:K,'1-2 人员岗位信息'!$C:$C,"专业外包",'1-2 人员岗位信息'!$B:$B,$D25) -> 0 | AU25: =AV25*AW25 -> 0 | AV25: =SUMIFS('1-2 人员岗位信息'!L:L,'1-2 人员岗位信息'!$C:$C,"专业外包",'1-2 人员岗位信息'!$B:$B,$D25) -> 0 | AX25: =AY25*AZ25 -> 0 | AY25: =SUMIFS('1-2 人员岗位信息'!M:M,'1-2 人员岗位信息'!$C:$C,"专业外包",'1-2 人员岗位信息'!$B:$B,$D25) -> 0 | BA25: =BB25*BC25 -> 0 | BB25: =SUMIFS('1-2 人员岗位信息'!N:N,'1-2 人员岗位信息'!$C:$C,"专业外包",'1-2 人员岗位信息'!$B:$B,$D25) -> 0 | BD25: =BE25*BF25 -> 0 | BE25: =SUMIFS('1-2 人员岗位信息'!O:O,'1-2 人员岗位信息'!$C:$C,"专业外包",'1-2 人员岗位信息'!$B:$B,$D25) -> 0 | BG25: =BH25*BI25 -> 0 | BH25: =SUMIFS('1-2 人员岗位信息'!P:P,'1-2 人员岗位信息'!$C:$C,"专业外包",'1-2 人员岗位信息'!$B:$B,$D25) -> 0 | BJ25: =BK25*BL25 -> 0 | BK25: =SUMIFS('1-2 人员岗位信息'!Q:Q,'1-2 人员岗位信息'!$C:$C,"专业外包",'1-2 人员岗位信息'!$B:$B,$D25) -> 0
